[2020-09-14 22:20:01,763][werkzeug][INFO] -  * Running on http://127.0.0.1:8081/ (Press CTRL+C to quit)
[2020-09-14 22:20:06,132][werkzeug][INFO] - 127.0.0.1 - - [14/Sep/2020 22:20:06] "[37mGET /set_filter/none/all/person/yes/none HTTP/1.1[0m" 200 -
[2020-09-14 22:20:06,138][w3classifier.app][ERROR] - Exception on /get_label_value_on_image/person/undefined [GET]
Traceback (most recent call last):
  File "/home/imt/.local/lib/python3.6/site-packages/pandas/core/indexes/base.py", line 2646, in get_loc
    return self._engine.get_loc(key)
  File "pandas/_libs/index.pyx", line 111, in pandas._libs.index.IndexEngine.get_loc
  File "pandas/_libs/index.pyx", line 138, in pandas._libs.index.IndexEngine.get_loc
  File "pandas/_libs/hashtable_class_helper.pxi", line 1619, in pandas._libs.hashtable.PyObjectHashTable.get_item
  File "pandas/_libs/hashtable_class_helper.pxi", line 1627, in pandas._libs.hashtable.PyObjectHashTable.get_item
KeyError: 'undefined'

During handling of the above exception, another exception occurred:

Traceback (most recent call last):
  File "/usr/local/lib/python3.6/dist-packages/flask/app.py", line 2447, in wsgi_app
    response = self.full_dispatch_request()
  File "/usr/local/lib/python3.6/dist-packages/flask/app.py", line 1952, in full_dispatch_request
    rv = self.handle_user_exception(e)
  File "/usr/local/lib/python3.6/dist-packages/flask_cors/extension.py", line 161, in wrapped_function
    return cors_after_request(app.make_response(f(*args, **kwargs)))
  File "/usr/local/lib/python3.6/dist-packages/flask/app.py", line 1821, in handle_user_exception
    reraise(exc_type, exc_value, tb)
  File "/usr/local/lib/python3.6/dist-packages/flask/_compat.py", line 39, in reraise
    raise value
  File "/usr/local/lib/python3.6/dist-packages/flask/app.py", line 1950, in full_dispatch_request
    rv = self.dispatch_request()
  File "/usr/local/lib/python3.6/dist-packages/flask/app.py", line 1936, in dispatch_request
    return self.view_functions[rule.endpoint](**req.view_args)
  File "/home/imt/work/pyqt5-images-classifier/w3classifier/app/views.py", line 59, in get_label_value_on_image
    return jsonify(dbs.get_label_value_on_image(label, im))
  File "/home/imt/work/pyqt5-images-classifier/w3classifier/app/module.py", line 217, in get_label_value_on_image
    return {'imlabel': self.main.at[im, label]}
  File "/home/imt/.local/lib/python3.6/site-packages/pandas/core/indexing.py", line 2179, in __getitem__
    return self.obj._get_value(*key, takeable=self._takeable)
  File "/home/imt/.local/lib/python3.6/site-packages/pandas/core/frame.py", line 2919, in _get_value
    index = self.index.get_loc(index)
  File "/home/imt/.local/lib/python3.6/site-packages/pandas/core/indexes/base.py", line 2648, in get_loc
    return self._engine.get_loc(self._maybe_cast_indexer(key))
  File "pandas/_libs/index.pyx", line 111, in pandas._libs.index.IndexEngine.get_loc
  File "pandas/_libs/index.pyx", line 138, in pandas._libs.index.IndexEngine.get_loc
  File "pandas/_libs/hashtable_class_helper.pxi", line 1619, in pandas._libs.hashtable.PyObjectHashTable.get_item
  File "pandas/_libs/hashtable_class_helper.pxi", line 1627, in pandas._libs.hashtable.PyObjectHashTable.get_item
KeyError: 'undefined'
[2020-09-14 22:20:06,140][werkzeug][INFO] - 127.0.0.1 - - [14/Sep/2020 22:20:06] "[35m[1mGET /get_label_value_on_image/person/undefined HTTP/1.1[0m" 500 -
