[2020-09-11 19:55:27,294][werkzeug][INFO] -  * Running on http://127.0.0.1:8081/ (Press CTRL+C to quit)
[2020-09-11 19:55:38,561][w3classifier.app][ERROR] - Exception on /set_filter/none/all/none/no/none [GET]
Traceback (most recent call last):
  File "/home/imt/.local/lib/python3.6/site-packages/pandas/core/indexes/base.py", line 2646, in get_loc
    return self._engine.get_loc(key)
  File "pandas/_libs/index.pyx", line 111, in pandas._libs.index.IndexEngine.get_loc
  File "pandas/_libs/index.pyx", line 138, in pandas._libs.index.IndexEngine.get_loc
  File "pandas/_libs/hashtable_class_helper.pxi", line 1619, in pandas._libs.hashtable.PyObjectHashTable.get_item
  File "pandas/_libs/hashtable_class_helper.pxi", line 1627, in pandas._libs.hashtable.PyObjectHashTable.get_item
KeyError: 'none'

During handling of the above exception, another exception occurred:

Traceback (most recent call last):
  File "/usr/local/lib/python3.6/dist-packages/flask/app.py", line 2447, in wsgi_app
    response = self.full_dispatch_request()
  File "/usr/local/lib/python3.6/dist-packages/flask/app.py", line 1952, in full_dispatch_request
    rv = self.handle_user_exception(e)
  File "/usr/local/lib/python3.6/dist-packages/flask_cors/extension.py", line 161, in wrapped_function
    return cors_after_request(app.make_response(f(*args, **kwargs)))
  File "/usr/local/lib/python3.6/dist-packages/flask/app.py", line 1821, in handle_user_exception
    reraise(exc_type, exc_value, tb)
  File "/usr/local/lib/python3.6/dist-packages/flask/_compat.py", line 39, in reraise
    raise value
  File "/usr/local/lib/python3.6/dist-packages/flask/app.py", line 1950, in full_dispatch_request
    rv = self.dispatch_request()
  File "/usr/local/lib/python3.6/dist-packages/flask/app.py", line 1936, in dispatch_request
    return self.view_functions[rule.endpoint](**req.view_args)
  File "/home/imt/work/pyqt5-images-classifier/w3classifier/app/views.py", line 53, in set_filter
    resp = jsonify(dbs.set_filter(label, value, seek_label, seek_only_clear, size))
  File "/home/imt/work/pyqt5-images-classifier/w3classifier/app/module.py", line 183, in set_filter
    f2 = self.main[label] == value
  File "/home/imt/.local/lib/python3.6/site-packages/pandas/core/frame.py", line 2800, in __getitem__
    indexer = self.columns.get_loc(key)
  File "/home/imt/.local/lib/python3.6/site-packages/pandas/core/indexes/base.py", line 2648, in get_loc
    return self._engine.get_loc(self._maybe_cast_indexer(key))
  File "pandas/_libs/index.pyx", line 111, in pandas._libs.index.IndexEngine.get_loc
  File "pandas/_libs/index.pyx", line 138, in pandas._libs.index.IndexEngine.get_loc
  File "pandas/_libs/hashtable_class_helper.pxi", line 1619, in pandas._libs.hashtable.PyObjectHashTable.get_item
  File "pandas/_libs/hashtable_class_helper.pxi", line 1627, in pandas._libs.hashtable.PyObjectHashTable.get_item
KeyError: 'none'
[2020-09-11 19:55:38,563][werkzeug][INFO] - 127.0.0.1 - - [11/Sep/2020 19:55:38] "[37mGET /marked_image/undefined HTTP/1.1[0m" 200 -
[2020-09-11 19:55:38,565][werkzeug][INFO] - 127.0.0.1 - - [11/Sep/2020 19:55:38] "[35m[1mGET /set_filter/none/all/none/no/none HTTP/1.1[0m" 500 -
[2020-09-11 19:55:47,578][w3classifier.app][ERROR] - Exception on /set_filter/none/all/none/no/up [GET]
Traceback (most recent call last):
  File "/home/imt/.local/lib/python3.6/site-packages/pandas/core/indexes/base.py", line 2646, in get_loc
    return self._engine.get_loc(key)
  File "pandas/_libs/index.pyx", line 111, in pandas._libs.index.IndexEngine.get_loc
  File "pandas/_libs/index.pyx", line 138, in pandas._libs.index.IndexEngine.get_loc
  File "pandas/_libs/hashtable_class_helper.pxi", line 1619, in pandas._libs.hashtable.PyObjectHashTable.get_item
  File "pandas/_libs/hashtable_class_helper.pxi", line 1627, in pandas._libs.hashtable.PyObjectHashTable.get_item
KeyError: 'none'

During handling of the above exception, another exception occurred:

Traceback (most recent call last):
  File "/usr/local/lib/python3.6/dist-packages/flask/app.py", line 2447, in wsgi_app
    response = self.full_dispatch_request()
  File "/usr/local/lib/python3.6/dist-packages/flask/app.py", line 1952, in full_dispatch_request
    rv = self.handle_user_exception(e)
  File "/usr/local/lib/python3.6/dist-packages/flask_cors/extension.py", line 161, in wrapped_function
    return cors_after_request(app.make_response(f(*args, **kwargs)))
  File "/usr/local/lib/python3.6/dist-packages/flask/app.py", line 1821, in handle_user_exception
    reraise(exc_type, exc_value, tb)
  File "/usr/local/lib/python3.6/dist-packages/flask/_compat.py", line 39, in reraise
    raise value
  File "/usr/local/lib/python3.6/dist-packages/flask/app.py", line 1950, in full_dispatch_request
    rv = self.dispatch_request()
  File "/usr/local/lib/python3.6/dist-packages/flask/app.py", line 1936, in dispatch_request
    return self.view_functions[rule.endpoint](**req.view_args)
  File "/home/imt/work/pyqt5-images-classifier/w3classifier/app/views.py", line 53, in set_filter
    resp = jsonify(dbs.set_filter(label, value, seek_label, seek_only_clear, size))
  File "/home/imt/work/pyqt5-images-classifier/w3classifier/app/module.py", line 183, in set_filter
    f2 = self.main[label] == value
  File "/home/imt/.local/lib/python3.6/site-packages/pandas/core/frame.py", line 2800, in __getitem__
    indexer = self.columns.get_loc(key)
  File "/home/imt/.local/lib/python3.6/site-packages/pandas/core/indexes/base.py", line 2648, in get_loc
    return self._engine.get_loc(self._maybe_cast_indexer(key))
  File "pandas/_libs/index.pyx", line 111, in pandas._libs.index.IndexEngine.get_loc
  File "pandas/_libs/index.pyx", line 138, in pandas._libs.index.IndexEngine.get_loc
  File "pandas/_libs/hashtable_class_helper.pxi", line 1619, in pandas._libs.hashtable.PyObjectHashTable.get_item
  File "pandas/_libs/hashtable_class_helper.pxi", line 1627, in pandas._libs.hashtable.PyObjectHashTable.get_item
KeyError: 'none'
[2020-09-11 19:55:47,580][werkzeug][INFO] - 127.0.0.1 - - [11/Sep/2020 19:55:47] "[35m[1mGET /set_filter/none/all/none/no/up HTTP/1.1[0m" 500 -
[2020-09-11 19:55:48,530][w3classifier.app][ERROR] - Exception on /set_filter/none/all/none/no/none [GET]
Traceback (most recent call last):
  File "/home/imt/.local/lib/python3.6/site-packages/pandas/core/indexes/base.py", line 2646, in get_loc
    return self._engine.get_loc(key)
  File "pandas/_libs/index.pyx", line 111, in pandas._libs.index.IndexEngine.get_loc
  File "pandas/_libs/index.pyx", line 138, in pandas._libs.index.IndexEngine.get_loc
  File "pandas/_libs/hashtable_class_helper.pxi", line 1619, in pandas._libs.hashtable.PyObjectHashTable.get_item
  File "pandas/_libs/hashtable_class_helper.pxi", line 1627, in pandas._libs.hashtable.PyObjectHashTable.get_item
KeyError: 'none'

During handling of the above exception, another exception occurred:

Traceback (most recent call last):
  File "/usr/local/lib/python3.6/dist-packages/flask/app.py", line 2447, in wsgi_app
    response = self.full_dispatch_request()
  File "/usr/local/lib/python3.6/dist-packages/flask/app.py", line 1952, in full_dispatch_request
    rv = self.handle_user_exception(e)
  File "/usr/local/lib/python3.6/dist-packages/flask_cors/extension.py", line 161, in wrapped_function
    return cors_after_request(app.make_response(f(*args, **kwargs)))
  File "/usr/local/lib/python3.6/dist-packages/flask/app.py", line 1821, in handle_user_exception
    reraise(exc_type, exc_value, tb)
  File "/usr/local/lib/python3.6/dist-packages/flask/_compat.py", line 39, in reraise
    raise value
  File "/usr/local/lib/python3.6/dist-packages/flask/app.py", line 1950, in full_dispatch_request
    rv = self.dispatch_request()
  File "/usr/local/lib/python3.6/dist-packages/flask/app.py", line 1936, in dispatch_request
    return self.view_functions[rule.endpoint](**req.view_args)
  File "/home/imt/work/pyqt5-images-classifier/w3classifier/app/views.py", line 53, in set_filter
    resp = jsonify(dbs.set_filter(label, value, seek_label, seek_only_clear, size))
  File "/home/imt/work/pyqt5-images-classifier/w3classifier/app/module.py", line 183, in set_filter
    f2 = self.main[label] == value
  File "/home/imt/.local/lib/python3.6/site-packages/pandas/core/frame.py", line 2800, in __getitem__
    indexer = self.columns.get_loc(key)
  File "/home/imt/.local/lib/python3.6/site-packages/pandas/core/indexes/base.py", line 2648, in get_loc
    return self._engine.get_loc(self._maybe_cast_indexer(key))
  File "pandas/_libs/index.pyx", line 111, in pandas._libs.index.IndexEngine.get_loc
  File "pandas/_libs/index.pyx", line 138, in pandas._libs.index.IndexEngine.get_loc
  File "pandas/_libs/hashtable_class_helper.pxi", line 1619, in pandas._libs.hashtable.PyObjectHashTable.get_item
  File "pandas/_libs/hashtable_class_helper.pxi", line 1627, in pandas._libs.hashtable.PyObjectHashTable.get_item
KeyError: 'none'
[2020-09-11 19:55:48,531][werkzeug][INFO] - 127.0.0.1 - - [11/Sep/2020 19:55:48] "[35m[1mGET /set_filter/none/all/none/no/none HTTP/1.1[0m" 500 -
[2020-09-11 19:55:49,250][w3classifier.app][ERROR] - Exception on /set_filter/none/all/none/no/none [GET]
Traceback (most recent call last):
  File "/home/imt/.local/lib/python3.6/site-packages/pandas/core/indexes/base.py", line 2646, in get_loc
    return self._engine.get_loc(key)
  File "pandas/_libs/index.pyx", line 111, in pandas._libs.index.IndexEngine.get_loc
  File "pandas/_libs/index.pyx", line 138, in pandas._libs.index.IndexEngine.get_loc
  File "pandas/_libs/hashtable_class_helper.pxi", line 1619, in pandas._libs.hashtable.PyObjectHashTable.get_item
  File "pandas/_libs/hashtable_class_helper.pxi", line 1627, in pandas._libs.hashtable.PyObjectHashTable.get_item
KeyError: 'none'

During handling of the above exception, another exception occurred:

Traceback (most recent call last):
  File "/usr/local/lib/python3.6/dist-packages/flask/app.py", line 2447, in wsgi_app
    response = self.full_dispatch_request()
  File "/usr/local/lib/python3.6/dist-packages/flask/app.py", line 1952, in full_dispatch_request
    rv = self.handle_user_exception(e)
  File "/usr/local/lib/python3.6/dist-packages/flask_cors/extension.py", line 161, in wrapped_function
    return cors_after_request(app.make_response(f(*args, **kwargs)))
  File "/usr/local/lib/python3.6/dist-packages/flask/app.py", line 1821, in handle_user_exception
    reraise(exc_type, exc_value, tb)
  File "/usr/local/lib/python3.6/dist-packages/flask/_compat.py", line 39, in reraise
    raise value
  File "/usr/local/lib/python3.6/dist-packages/flask/app.py", line 1950, in full_dispatch_request
    rv = self.dispatch_request()
  File "/usr/local/lib/python3.6/dist-packages/flask/app.py", line 1936, in dispatch_request
    return self.view_functions[rule.endpoint](**req.view_args)
  File "/home/imt/work/pyqt5-images-classifier/w3classifier/app/views.py", line 53, in set_filter
    resp = jsonify(dbs.set_filter(label, value, seek_label, seek_only_clear, size))
  File "/home/imt/work/pyqt5-images-classifier/w3classifier/app/module.py", line 183, in set_filter
    f2 = self.main[label] == value
  File "/home/imt/.local/lib/python3.6/site-packages/pandas/core/frame.py", line 2800, in __getitem__
    indexer = self.columns.get_loc(key)
  File "/home/imt/.local/lib/python3.6/site-packages/pandas/core/indexes/base.py", line 2648, in get_loc
    return self._engine.get_loc(self._maybe_cast_indexer(key))
  File "pandas/_libs/index.pyx", line 111, in pandas._libs.index.IndexEngine.get_loc
  File "pandas/_libs/index.pyx", line 138, in pandas._libs.index.IndexEngine.get_loc
  File "pandas/_libs/hashtable_class_helper.pxi", line 1619, in pandas._libs.hashtable.PyObjectHashTable.get_item
  File "pandas/_libs/hashtable_class_helper.pxi", line 1627, in pandas._libs.hashtable.PyObjectHashTable.get_item
KeyError: 'none'
[2020-09-11 19:55:49,252][werkzeug][INFO] - 127.0.0.1 - - [11/Sep/2020 19:55:49] "[35m[1mGET /set_filter/none/all/none/no/none HTTP/1.1[0m" 500 -
[2020-09-11 19:55:52,318][werkzeug][INFO] - 127.0.0.1 - - [11/Sep/2020 19:55:52] "[37mGET /marked_image/undefined HTTP/1.1[0m" 200 -
[2020-09-11 19:55:52,322][w3classifier.app][ERROR] - Exception on /set_filter/none/all/none/no/none [GET]
Traceback (most recent call last):
  File "/home/imt/.local/lib/python3.6/site-packages/pandas/core/indexes/base.py", line 2646, in get_loc
    return self._engine.get_loc(key)
  File "pandas/_libs/index.pyx", line 111, in pandas._libs.index.IndexEngine.get_loc
  File "pandas/_libs/index.pyx", line 138, in pandas._libs.index.IndexEngine.get_loc
  File "pandas/_libs/hashtable_class_helper.pxi", line 1619, in pandas._libs.hashtable.PyObjectHashTable.get_item
  File "pandas/_libs/hashtable_class_helper.pxi", line 1627, in pandas._libs.hashtable.PyObjectHashTable.get_item
KeyError: 'none'

During handling of the above exception, another exception occurred:

Traceback (most recent call last):
  File "/usr/local/lib/python3.6/dist-packages/flask/app.py", line 2447, in wsgi_app
    response = self.full_dispatch_request()
  File "/usr/local/lib/python3.6/dist-packages/flask/app.py", line 1952, in full_dispatch_request
    rv = self.handle_user_exception(e)
  File "/usr/local/lib/python3.6/dist-packages/flask_cors/extension.py", line 161, in wrapped_function
    return cors_after_request(app.make_response(f(*args, **kwargs)))
  File "/usr/local/lib/python3.6/dist-packages/flask/app.py", line 1821, in handle_user_exception
    reraise(exc_type, exc_value, tb)
  File "/usr/local/lib/python3.6/dist-packages/flask/_compat.py", line 39, in reraise
    raise value
  File "/usr/local/lib/python3.6/dist-packages/flask/app.py", line 1950, in full_dispatch_request
    rv = self.dispatch_request()
  File "/usr/local/lib/python3.6/dist-packages/flask/app.py", line 1936, in dispatch_request
    return self.view_functions[rule.endpoint](**req.view_args)
  File "/home/imt/work/pyqt5-images-classifier/w3classifier/app/views.py", line 53, in set_filter
    resp = jsonify(dbs.set_filter(label, value, seek_label, seek_only_clear, size))
  File "/home/imt/work/pyqt5-images-classifier/w3classifier/app/module.py", line 183, in set_filter
    f2 = self.main[label] == value
  File "/home/imt/.local/lib/python3.6/site-packages/pandas/core/frame.py", line 2800, in __getitem__
    indexer = self.columns.get_loc(key)
  File "/home/imt/.local/lib/python3.6/site-packages/pandas/core/indexes/base.py", line 2648, in get_loc
    return self._engine.get_loc(self._maybe_cast_indexer(key))
  File "pandas/_libs/index.pyx", line 111, in pandas._libs.index.IndexEngine.get_loc
  File "pandas/_libs/index.pyx", line 138, in pandas._libs.index.IndexEngine.get_loc
  File "pandas/_libs/hashtable_class_helper.pxi", line 1619, in pandas._libs.hashtable.PyObjectHashTable.get_item
  File "pandas/_libs/hashtable_class_helper.pxi", line 1627, in pandas._libs.hashtable.PyObjectHashTable.get_item
KeyError: 'none'
[2020-09-11 19:55:52,324][werkzeug][INFO] - 127.0.0.1 - - [11/Sep/2020 19:55:52] "[35m[1mGET /set_filter/none/all/none/no/none HTTP/1.1[0m" 500 -
