[2020-09-14 21:37:59,304][werkzeug][INFO] -  * Running on http://127.0.0.1:8081/ (Press CTRL+C to quit)
[2020-09-14 21:38:03,816][werkzeug][INFO] - 127.0.0.1 - - [14/Sep/2020 21:38:03] "[37mGET /set_filter/none/all/person/yes/none HTTP/1.1[0m" 200 -
[2020-09-14 21:38:03,821][werkzeug][INFO] - 127.0.0.1 - - [14/Sep/2020 21:38:03] "[37mGET /get_label_value_on_image/person/0912__19_08_11__i0000336__gcn1599926889446581__1599926889460772__person___________.png HTTP/1.1[0m" 200 -
[2020-09-14 21:38:05,218][werkzeug][INFO] - 127.0.0.1 - - [14/Sep/2020 21:38:05] "[37mGET /set_filter/none/all/person/yes/none HTTP/1.1[0m" 200 -
[2020-09-14 21:38:05,221][werkzeug][INFO] - 127.0.0.1 - - [14/Sep/2020 21:38:05] "[37mGET /get_label_value_on_image/person/0912__19_08_11__i0000336__gcn1599926889446581__1599926889460772__person___________.png HTTP/1.1[0m" 200 -
[2020-09-14 21:38:05,776][werkzeug][INFO] - 127.0.0.1 - - [14/Sep/2020 21:38:05] "[37mGET /set_filter/none/all/person/yes/none HTTP/1.1[0m" 200 -
[2020-09-14 21:38:05,779][werkzeug][INFO] - 127.0.0.1 - - [14/Sep/2020 21:38:05] "[37mGET /get_label_value_on_image/person/0912__19_08_11__i0000336__gcn1599926889446581__1599926889460772__person___________.png HTTP/1.1[0m" 200 -
[2020-09-14 21:38:06,083][werkzeug][INFO] - 127.0.0.1 - - [14/Sep/2020 21:38:06] "[37mGET /set_filter/none/all/person/yes/none HTTP/1.1[0m" 200 -
[2020-09-14 21:38:06,087][werkzeug][INFO] - 127.0.0.1 - - [14/Sep/2020 21:38:06] "[37mGET /get_label_value_on_image/person/0912__19_08_11__i0000336__gcn1599926889446581__1599926889460772__person___________.png HTTP/1.1[0m" 200 -
[2020-09-14 21:38:06,920][werkzeug][INFO] - 127.0.0.1 - - [14/Sep/2020 21:38:06] "[37mGET /set_filter/none/all/person/yes/none HTTP/1.1[0m" 200 -
[2020-09-14 21:38:06,924][werkzeug][INFO] - 127.0.0.1 - - [14/Sep/2020 21:38:06] "[37mGET /get_label_value_on_image/person/0912__19_08_11__i0000336__gcn1599926889446581__1599926889460772__person___________.png HTTP/1.1[0m" 200 -
[2020-09-14 21:38:08,590][werkzeug][INFO] - 127.0.0.1 - - [14/Sep/2020 21:38:08] "[37mGET /set_filter/none/all/person/yes/none HTTP/1.1[0m" 200 -
[2020-09-14 21:38:08,594][werkzeug][INFO] - 127.0.0.1 - - [14/Sep/2020 21:38:08] "[37mGET /get_label_value_on_image/person/0912__19_08_11__i0000336__gcn1599926889446581__1599926889460772__person___________.png HTTP/1.1[0m" 200 -
[2020-09-14 21:38:25,634][werkzeug][INFO] - 127.0.0.1 - - [14/Sep/2020 21:38:25] "[37mGET /set_value/0912__19_08_11__i0000336__gcn1599926889446581__1599926889460772__person___________.png/person/wrong HTTP/1.1[0m" 200 -
[2020-09-14 21:38:25,988][werkzeug][INFO] - 127.0.0.1 - - [14/Sep/2020 21:38:25] "[37mGET /get_label_value_on_image/person/0912__19_13_17__i0002425__gcn1599927015633316__1599927195658846__person___________.png HTTP/1.1[0m" 200 -
[2020-09-14 21:38:26,344][werkzeug][INFO] - 127.0.0.1 - - [14/Sep/2020 21:38:26] "[37mGET /set_value/0912__19_13_17__i0002425__gcn1599927015633316__1599927195658846__person___________.png/person/wrong HTTP/1.1[0m" 200 -
[2020-09-14 21:38:26,566][werkzeug][INFO] - 127.0.0.1 - - [14/Sep/2020 21:38:26] "[37mGET /get_label_value_on_image/person/0912__19_16_10__i0004160__gcn1599927015633316__1599927369402324__person___________.png HTTP/1.1[0m" 200 -
[2020-09-14 21:38:26,910][werkzeug][INFO] - 127.0.0.1 - - [14/Sep/2020 21:38:26] "[37mGET /set_value/0912__19_16_10__i0004160__gcn1599927015633316__1599927369402324__person___________.png/person/wrong HTTP/1.1[0m" 200 -
[2020-09-14 21:38:27,094][werkzeug][INFO] - 127.0.0.1 - - [14/Sep/2020 21:38:27] "[37mGET /get_label_value_on_image/person/0912__19_16_11__i0004161__gcn1599927015633316__1599927369435039__person___________.png HTTP/1.1[0m" 200 -
[2020-09-14 21:38:27,451][werkzeug][INFO] - 127.0.0.1 - - [14/Sep/2020 21:38:27] "[37mGET /set_value/0912__19_16_11__i0004161__gcn1599927015633316__1599927369435039__person___________.png/person/wrong HTTP/1.1[0m" 200 -
[2020-09-14 21:38:27,623][werkzeug][INFO] - 127.0.0.1 - - [14/Sep/2020 21:38:27] "[37mGET /get_label_value_on_image/person/0912__19_17_13__i0004758__gcn1599927015633316__1599927431808771__person___________.png HTTP/1.1[0m" 200 -
[2020-09-14 21:38:27,943][werkzeug][INFO] - 127.0.0.1 - - [14/Sep/2020 21:38:27] "[37mGET /set_value/0912__19_17_13__i0004758__gcn1599927015633316__1599927431808771__person___________.png/person/wrong HTTP/1.1[0m" 200 -
[2020-09-14 21:38:28,182][werkzeug][INFO] - 127.0.0.1 - - [14/Sep/2020 21:38:28] "[37mGET /get_label_value_on_image/person/0912__19_17_18__i0004821__gcn1599927015633316__1599927436858245__person___________.png HTTP/1.1[0m" 200 -
[2020-09-14 21:38:28,509][werkzeug][INFO] - 127.0.0.1 - - [14/Sep/2020 21:38:28] "[37mGET /set_value/0912__19_17_18__i0004821__gcn1599927015633316__1599927436858245__person___________.png/person/wrong HTTP/1.1[0m" 200 -
[2020-09-14 21:38:28,720][w3classifier.app][ERROR] - Exception on /get_label_value_on_image/person/undefined [GET]
Traceback (most recent call last):
  File "/home/imt/.local/lib/python3.6/site-packages/pandas/core/indexes/base.py", line 2646, in get_loc
    return self._engine.get_loc(key)
  File "pandas/_libs/index.pyx", line 111, in pandas._libs.index.IndexEngine.get_loc
  File "pandas/_libs/index.pyx", line 138, in pandas._libs.index.IndexEngine.get_loc
  File "pandas/_libs/hashtable_class_helper.pxi", line 1619, in pandas._libs.hashtable.PyObjectHashTable.get_item
  File "pandas/_libs/hashtable_class_helper.pxi", line 1627, in pandas._libs.hashtable.PyObjectHashTable.get_item
KeyError: 'undefined'

During handling of the above exception, another exception occurred:

Traceback (most recent call last):
  File "/usr/local/lib/python3.6/dist-packages/flask/app.py", line 2447, in wsgi_app
    response = self.full_dispatch_request()
  File "/usr/local/lib/python3.6/dist-packages/flask/app.py", line 1952, in full_dispatch_request
    rv = self.handle_user_exception(e)
  File "/usr/local/lib/python3.6/dist-packages/flask_cors/extension.py", line 161, in wrapped_function
    return cors_after_request(app.make_response(f(*args, **kwargs)))
  File "/usr/local/lib/python3.6/dist-packages/flask/app.py", line 1821, in handle_user_exception
    reraise(exc_type, exc_value, tb)
  File "/usr/local/lib/python3.6/dist-packages/flask/_compat.py", line 39, in reraise
    raise value
  File "/usr/local/lib/python3.6/dist-packages/flask/app.py", line 1950, in full_dispatch_request
    rv = self.dispatch_request()
  File "/usr/local/lib/python3.6/dist-packages/flask/app.py", line 1936, in dispatch_request
    return self.view_functions[rule.endpoint](**req.view_args)
  File "/home/imt/work/pyqt5-images-classifier/w3classifier/app/views.py", line 59, in get_label_value_on_image
    return jsonify(dbs.get_label_value_on_image(label, im))
  File "/home/imt/work/pyqt5-images-classifier/w3classifier/app/module.py", line 214, in get_label_value_on_image
    return {'imlabel': self.main.at[im, label]}
  File "/home/imt/.local/lib/python3.6/site-packages/pandas/core/indexing.py", line 2179, in __getitem__
    return self.obj._get_value(*key, takeable=self._takeable)
  File "/home/imt/.local/lib/python3.6/site-packages/pandas/core/frame.py", line 2919, in _get_value
    index = self.index.get_loc(index)
  File "/home/imt/.local/lib/python3.6/site-packages/pandas/core/indexes/base.py", line 2648, in get_loc
    return self._engine.get_loc(self._maybe_cast_indexer(key))
  File "pandas/_libs/index.pyx", line 111, in pandas._libs.index.IndexEngine.get_loc
  File "pandas/_libs/index.pyx", line 138, in pandas._libs.index.IndexEngine.get_loc
  File "pandas/_libs/hashtable_class_helper.pxi", line 1619, in pandas._libs.hashtable.PyObjectHashTable.get_item
  File "pandas/_libs/hashtable_class_helper.pxi", line 1627, in pandas._libs.hashtable.PyObjectHashTable.get_item
KeyError: 'undefined'
[2020-09-14 21:38:28,723][werkzeug][INFO] - 127.0.0.1 - - [14/Sep/2020 21:38:28] "[37mGET /marked_image/undefined HTTP/1.1[0m" 200 -
[2020-09-14 21:38:28,735][werkzeug][INFO] - 127.0.0.1 - - [14/Sep/2020 21:38:28] "[35m[1mGET /get_label_value_on_image/person/undefined HTTP/1.1[0m" 500 -
[2020-09-14 21:38:30,704][werkzeug][INFO] - 127.0.0.1 - - [14/Sep/2020 21:38:30] "[37mGET /store_label/person HTTP/1.1[0m" 200 -
[2020-09-14 21:39:12,014][werkzeug][INFO] - 127.0.0.1 - - [14/Sep/2020 21:39:12] "[37mGET /set_filter/none/all/none/no/none HTTP/1.1[0m" 200 -
[2020-09-14 21:39:12,015][werkzeug][INFO] - 127.0.0.1 - - [14/Sep/2020 21:39:12] "[37mGET /marked_image/undefined HTTP/1.1[0m" 200 -
[2020-09-14 21:39:12,045][werkzeug][INFO] - 127.0.0.1 - - [14/Sep/2020 21:39:12] "[37mGET /get_label_value_on_image/none/0103_15_07_56_i4981_id276_cn1578064077907896000_thr540.In%20.jpg HTTP/1.1[0m" 200 -
[2020-09-14 21:39:12,048][werkzeug][INFO] - 127.0.0.1 - - [14/Sep/2020 21:39:12] "[37mGET /marked_image/0103_15_07_56_i4981_id276_cn1578064077907896000_thr540.In%20.jpg HTTP/1.1[0m" 200 -
[2020-09-14 21:39:12,976][werkzeug][INFO] - 127.0.0.1 - - [14/Sep/2020 21:39:12] "[37mGET /marked_image/undefined HTTP/1.1[0m" 200 -
[2020-09-14 21:39:13,004][werkzeug][INFO] - 127.0.0.1 - - [14/Sep/2020 21:39:13] "[37mGET /set_filter/none/all/none/no/none HTTP/1.1[0m" 200 -
[2020-09-14 21:39:13,032][werkzeug][INFO] - 127.0.0.1 - - [14/Sep/2020 21:39:13] "[37mGET /get_label_value_on_image/none/0103_15_07_56_i4981_id276_cn1578064077907896000_thr540.In%20.jpg HTTP/1.1[0m" 200 -
[2020-09-14 21:39:13,034][werkzeug][INFO] - 127.0.0.1 - - [14/Sep/2020 21:39:13] "[37mGET /marked_image/0103_15_07_56_i4981_id276_cn1578064077907896000_thr540.In%20.jpg HTTP/1.1[0m" 200 -
[2020-09-14 21:39:15,730][werkzeug][INFO] - 127.0.0.1 - - [14/Sep/2020 21:39:15] "[37mGET /set_filter/none/all/person/no/none HTTP/1.1[0m" 200 -
[2020-09-14 21:39:15,750][werkzeug][INFO] - 127.0.0.1 - - [14/Sep/2020 21:39:15] "[37mGET /get_label_value_on_image/person/0103_15_07_56_i4981_id276_cn1578064077907896000_thr540.In%20.jpg HTTP/1.1[0m" 200 -
[2020-09-14 21:39:16,840][werkzeug][INFO] - 127.0.0.1 - - [14/Sep/2020 21:39:16] "[37mGET /set_filter/none/all/person/yes/none HTTP/1.1[0m" 200 -
[2020-09-14 21:39:16,842][w3classifier.app][ERROR] - Exception on /get_label_value_on_image/person/undefined [GET]
Traceback (most recent call last):
  File "/home/imt/.local/lib/python3.6/site-packages/pandas/core/indexes/base.py", line 2646, in get_loc
    return self._engine.get_loc(key)
  File "pandas/_libs/index.pyx", line 111, in pandas._libs.index.IndexEngine.get_loc
  File "pandas/_libs/index.pyx", line 138, in pandas._libs.index.IndexEngine.get_loc
  File "pandas/_libs/hashtable_class_helper.pxi", line 1619, in pandas._libs.hashtable.PyObjectHashTable.get_item
  File "pandas/_libs/hashtable_class_helper.pxi", line 1627, in pandas._libs.hashtable.PyObjectHashTable.get_item
KeyError: 'undefined'

During handling of the above exception, another exception occurred:

Traceback (most recent call last):
  File "/usr/local/lib/python3.6/dist-packages/flask/app.py", line 2447, in wsgi_app
    response = self.full_dispatch_request()
  File "/usr/local/lib/python3.6/dist-packages/flask/app.py", line 1952, in full_dispatch_request
    rv = self.handle_user_exception(e)
  File "/usr/local/lib/python3.6/dist-packages/flask_cors/extension.py", line 161, in wrapped_function
    return cors_after_request(app.make_response(f(*args, **kwargs)))
  File "/usr/local/lib/python3.6/dist-packages/flask/app.py", line 1821, in handle_user_exception
    reraise(exc_type, exc_value, tb)
  File "/usr/local/lib/python3.6/dist-packages/flask/_compat.py", line 39, in reraise
    raise value
  File "/usr/local/lib/python3.6/dist-packages/flask/app.py", line 1950, in full_dispatch_request
    rv = self.dispatch_request()
  File "/usr/local/lib/python3.6/dist-packages/flask/app.py", line 1936, in dispatch_request
    return self.view_functions[rule.endpoint](**req.view_args)
  File "/home/imt/work/pyqt5-images-classifier/w3classifier/app/views.py", line 59, in get_label_value_on_image
    return jsonify(dbs.get_label_value_on_image(label, im))
  File "/home/imt/work/pyqt5-images-classifier/w3classifier/app/module.py", line 214, in get_label_value_on_image
    return {'imlabel': self.main.at[im, label]}
  File "/home/imt/.local/lib/python3.6/site-packages/pandas/core/indexing.py", line 2179, in __getitem__
    return self.obj._get_value(*key, takeable=self._takeable)
  File "/home/imt/.local/lib/python3.6/site-packages/pandas/core/frame.py", line 2919, in _get_value
    index = self.index.get_loc(index)
  File "/home/imt/.local/lib/python3.6/site-packages/pandas/core/indexes/base.py", line 2648, in get_loc
    return self._engine.get_loc(self._maybe_cast_indexer(key))
  File "pandas/_libs/index.pyx", line 111, in pandas._libs.index.IndexEngine.get_loc
  File "pandas/_libs/index.pyx", line 138, in pandas._libs.index.IndexEngine.get_loc
  File "pandas/_libs/hashtable_class_helper.pxi", line 1619, in pandas._libs.hashtable.PyObjectHashTable.get_item
  File "pandas/_libs/hashtable_class_helper.pxi", line 1627, in pandas._libs.hashtable.PyObjectHashTable.get_item
KeyError: 'undefined'
[2020-09-14 21:39:16,843][werkzeug][INFO] - 127.0.0.1 - - [14/Sep/2020 21:39:16] "[35m[1mGET /get_label_value_on_image/person/undefined HTTP/1.1[0m" 500 -
[2020-09-14 21:39:16,844][werkzeug][INFO] - 127.0.0.1 - - [14/Sep/2020 21:39:16] "[37mGET /marked_image/undefined HTTP/1.1[0m" 200 -
[2020-09-14 21:39:20,601][werkzeug][INFO] - 127.0.0.1 - - [14/Sep/2020 21:39:20] "[37mGET /set_filter/none/all/person/no/none HTTP/1.1[0m" 200 -
[2020-09-14 21:39:20,616][werkzeug][INFO] - 127.0.0.1 - - [14/Sep/2020 21:39:20] "[37mGET /get_label_value_on_image/person/0103_15_07_56_i4981_id276_cn1578064077907896000_thr540.In%20.jpg HTTP/1.1[0m" 200 -
[2020-09-14 21:42:12,690][werkzeug][INFO] - 127.0.0.1 - - [14/Sep/2020 21:42:12] "[37mGET /set_filter/none/all/none/no/none HTTP/1.1[0m" 200 -
[2020-09-14 21:42:12,690][werkzeug][INFO] - 127.0.0.1 - - [14/Sep/2020 21:42:12] "[37mGET /marked_image/undefined HTTP/1.1[0m" 200 -
[2020-09-14 21:42:12,724][werkzeug][INFO] - 127.0.0.1 - - [14/Sep/2020 21:42:12] "[37mGET /get_label_value_on_image/none/0103_15_07_56_i4981_id276_cn1578064077907896000_thr540.In%20.jpg HTTP/1.1[0m" 200 -
[2020-09-14 21:42:12,727][werkzeug][INFO] - 127.0.0.1 - - [14/Sep/2020 21:42:12] "[37mGET /marked_image/0103_15_07_56_i4981_id276_cn1578064077907896000_thr540.In%20.jpg HTTP/1.1[0m" 200 -
[2020-09-14 21:42:18,214][werkzeug][INFO] - 127.0.0.1 - - [14/Sep/2020 21:42:18] "[37mGET /set_filter/none/all/none/yes/none HTTP/1.1[0m" 200 -
[2020-09-14 21:42:18,245][werkzeug][INFO] - 127.0.0.1 - - [14/Sep/2020 21:42:18] "[37mGET /get_label_value_on_image/none/0103_15_07_56_i4981_id276_cn1578064077907896000_thr540.In%20.jpg HTTP/1.1[0m" 200 -
[2020-09-14 21:42:19,349][werkzeug][INFO] - 127.0.0.1 - - [14/Sep/2020 21:42:19] "[37mGET /set_filter/none/all/none/yes/none HTTP/1.1[0m" 200 -
[2020-09-14 21:42:19,371][werkzeug][INFO] - 127.0.0.1 - - [14/Sep/2020 21:42:19] "[37mGET /get_label_value_on_image/none/0103_15_07_56_i4981_id276_cn1578064077907896000_thr540.In%20.jpg HTTP/1.1[0m" 200 -
[2020-09-14 21:42:20,093][werkzeug][INFO] - 127.0.0.1 - - [14/Sep/2020 21:42:20] "[37mGET /set_filter/none/all/person/yes/none HTTP/1.1[0m" 200 -
[2020-09-14 21:42:20,096][w3classifier.app][ERROR] - Exception on /get_label_value_on_image/person/undefined [GET]
Traceback (most recent call last):
  File "/home/imt/.local/lib/python3.6/site-packages/pandas/core/indexes/base.py", line 2646, in get_loc
    return self._engine.get_loc(key)
  File "pandas/_libs/index.pyx", line 111, in pandas._libs.index.IndexEngine.get_loc
  File "pandas/_libs/index.pyx", line 138, in pandas._libs.index.IndexEngine.get_loc
  File "pandas/_libs/hashtable_class_helper.pxi", line 1619, in pandas._libs.hashtable.PyObjectHashTable.get_item
  File "pandas/_libs/hashtable_class_helper.pxi", line 1627, in pandas._libs.hashtable.PyObjectHashTable.get_item
KeyError: 'undefined'

During handling of the above exception, another exception occurred:

Traceback (most recent call last):
  File "/usr/local/lib/python3.6/dist-packages/flask/app.py", line 2447, in wsgi_app
    response = self.full_dispatch_request()
  File "/usr/local/lib/python3.6/dist-packages/flask/app.py", line 1952, in full_dispatch_request
    rv = self.handle_user_exception(e)
  File "/usr/local/lib/python3.6/dist-packages/flask_cors/extension.py", line 161, in wrapped_function
    return cors_after_request(app.make_response(f(*args, **kwargs)))
  File "/usr/local/lib/python3.6/dist-packages/flask/app.py", line 1821, in handle_user_exception
    reraise(exc_type, exc_value, tb)
  File "/usr/local/lib/python3.6/dist-packages/flask/_compat.py", line 39, in reraise
    raise value
  File "/usr/local/lib/python3.6/dist-packages/flask/app.py", line 1950, in full_dispatch_request
    rv = self.dispatch_request()
  File "/usr/local/lib/python3.6/dist-packages/flask/app.py", line 1936, in dispatch_request
    return self.view_functions[rule.endpoint](**req.view_args)
  File "/home/imt/work/pyqt5-images-classifier/w3classifier/app/views.py", line 59, in get_label_value_on_image
    return jsonify(dbs.get_label_value_on_image(label, im))
  File "/home/imt/work/pyqt5-images-classifier/w3classifier/app/module.py", line 214, in get_label_value_on_image
    return {'imlabel': self.main.at[im, label]}
  File "/home/imt/.local/lib/python3.6/site-packages/pandas/core/indexing.py", line 2179, in __getitem__
    return self.obj._get_value(*key, takeable=self._takeable)
  File "/home/imt/.local/lib/python3.6/site-packages/pandas/core/frame.py", line 2919, in _get_value
    index = self.index.get_loc(index)
  File "/home/imt/.local/lib/python3.6/site-packages/pandas/core/indexes/base.py", line 2648, in get_loc
    return self._engine.get_loc(self._maybe_cast_indexer(key))
  File "pandas/_libs/index.pyx", line 111, in pandas._libs.index.IndexEngine.get_loc
  File "pandas/_libs/index.pyx", line 138, in pandas._libs.index.IndexEngine.get_loc
  File "pandas/_libs/hashtable_class_helper.pxi", line 1619, in pandas._libs.hashtable.PyObjectHashTable.get_item
  File "pandas/_libs/hashtable_class_helper.pxi", line 1627, in pandas._libs.hashtable.PyObjectHashTable.get_item
KeyError: 'undefined'
[2020-09-14 21:42:20,097][werkzeug][INFO] - 127.0.0.1 - - [14/Sep/2020 21:42:20] "[35m[1mGET /get_label_value_on_image/person/undefined HTTP/1.1[0m" 500 -
[2020-09-14 21:42:20,098][werkzeug][INFO] - 127.0.0.1 - - [14/Sep/2020 21:42:20] "[37mGET /marked_image/undefined HTTP/1.1[0m" 200 -
[2020-09-14 21:42:21,418][werkzeug][INFO] - 127.0.0.1 - - [14/Sep/2020 21:42:21] "[37mGET /set_filter/none/all/person/yes/none HTTP/1.1[0m" 200 -
[2020-09-14 21:42:21,421][w3classifier.app][ERROR] - Exception on /get_label_value_on_image/person/undefined [GET]
Traceback (most recent call last):
  File "/home/imt/.local/lib/python3.6/site-packages/pandas/core/indexes/base.py", line 2646, in get_loc
    return self._engine.get_loc(key)
  File "pandas/_libs/index.pyx", line 111, in pandas._libs.index.IndexEngine.get_loc
  File "pandas/_libs/index.pyx", line 138, in pandas._libs.index.IndexEngine.get_loc
  File "pandas/_libs/hashtable_class_helper.pxi", line 1619, in pandas._libs.hashtable.PyObjectHashTable.get_item
  File "pandas/_libs/hashtable_class_helper.pxi", line 1627, in pandas._libs.hashtable.PyObjectHashTable.get_item
KeyError: 'undefined'

During handling of the above exception, another exception occurred:

Traceback (most recent call last):
  File "/usr/local/lib/python3.6/dist-packages/flask/app.py", line 2447, in wsgi_app
    response = self.full_dispatch_request()
  File "/usr/local/lib/python3.6/dist-packages/flask/app.py", line 1952, in full_dispatch_request
    rv = self.handle_user_exception(e)
  File "/usr/local/lib/python3.6/dist-packages/flask_cors/extension.py", line 161, in wrapped_function
    return cors_after_request(app.make_response(f(*args, **kwargs)))
  File "/usr/local/lib/python3.6/dist-packages/flask/app.py", line 1821, in handle_user_exception
    reraise(exc_type, exc_value, tb)
  File "/usr/local/lib/python3.6/dist-packages/flask/_compat.py", line 39, in reraise
    raise value
  File "/usr/local/lib/python3.6/dist-packages/flask/app.py", line 1950, in full_dispatch_request
    rv = self.dispatch_request()
  File "/usr/local/lib/python3.6/dist-packages/flask/app.py", line 1936, in dispatch_request
    return self.view_functions[rule.endpoint](**req.view_args)
  File "/home/imt/work/pyqt5-images-classifier/w3classifier/app/views.py", line 59, in get_label_value_on_image
    return jsonify(dbs.get_label_value_on_image(label, im))
  File "/home/imt/work/pyqt5-images-classifier/w3classifier/app/module.py", line 214, in get_label_value_on_image
    return {'imlabel': self.main.at[im, label]}
  File "/home/imt/.local/lib/python3.6/site-packages/pandas/core/indexing.py", line 2179, in __getitem__
    return self.obj._get_value(*key, takeable=self._takeable)
  File "/home/imt/.local/lib/python3.6/site-packages/pandas/core/frame.py", line 2919, in _get_value
    index = self.index.get_loc(index)
  File "/home/imt/.local/lib/python3.6/site-packages/pandas/core/indexes/base.py", line 2648, in get_loc
    return self._engine.get_loc(self._maybe_cast_indexer(key))
  File "pandas/_libs/index.pyx", line 111, in pandas._libs.index.IndexEngine.get_loc
  File "pandas/_libs/index.pyx", line 138, in pandas._libs.index.IndexEngine.get_loc
  File "pandas/_libs/hashtable_class_helper.pxi", line 1619, in pandas._libs.hashtable.PyObjectHashTable.get_item
  File "pandas/_libs/hashtable_class_helper.pxi", line 1627, in pandas._libs.hashtable.PyObjectHashTable.get_item
KeyError: 'undefined'
[2020-09-14 21:42:21,421][werkzeug][INFO] - 127.0.0.1 - - [14/Sep/2020 21:42:21] "[35m[1mGET /get_label_value_on_image/person/undefined HTTP/1.1[0m" 500 -
[2020-09-14 21:42:22,051][werkzeug][INFO] - 127.0.0.1 - - [14/Sep/2020 21:42:22] "[37mGET /set_filter/none/all/person/yes/none HTTP/1.1[0m" 200 -
[2020-09-14 21:42:22,055][w3classifier.app][ERROR] - Exception on /get_label_value_on_image/person/undefined [GET]
Traceback (most recent call last):
  File "/home/imt/.local/lib/python3.6/site-packages/pandas/core/indexes/base.py", line 2646, in get_loc
    return self._engine.get_loc(key)
  File "pandas/_libs/index.pyx", line 111, in pandas._libs.index.IndexEngine.get_loc
  File "pandas/_libs/index.pyx", line 138, in pandas._libs.index.IndexEngine.get_loc
  File "pandas/_libs/hashtable_class_helper.pxi", line 1619, in pandas._libs.hashtable.PyObjectHashTable.get_item
  File "pandas/_libs/hashtable_class_helper.pxi", line 1627, in pandas._libs.hashtable.PyObjectHashTable.get_item
KeyError: 'undefined'

During handling of the above exception, another exception occurred:

Traceback (most recent call last):
  File "/usr/local/lib/python3.6/dist-packages/flask/app.py", line 2447, in wsgi_app
    response = self.full_dispatch_request()
  File "/usr/local/lib/python3.6/dist-packages/flask/app.py", line 1952, in full_dispatch_request
    rv = self.handle_user_exception(e)
  File "/usr/local/lib/python3.6/dist-packages/flask_cors/extension.py", line 161, in wrapped_function
    return cors_after_request(app.make_response(f(*args, **kwargs)))
  File "/usr/local/lib/python3.6/dist-packages/flask/app.py", line 1821, in handle_user_exception
    reraise(exc_type, exc_value, tb)
  File "/usr/local/lib/python3.6/dist-packages/flask/_compat.py", line 39, in reraise
    raise value
  File "/usr/local/lib/python3.6/dist-packages/flask/app.py", line 1950, in full_dispatch_request
    rv = self.dispatch_request()
  File "/usr/local/lib/python3.6/dist-packages/flask/app.py", line 1936, in dispatch_request
    return self.view_functions[rule.endpoint](**req.view_args)
  File "/home/imt/work/pyqt5-images-classifier/w3classifier/app/views.py", line 59, in get_label_value_on_image
    return jsonify(dbs.get_label_value_on_image(label, im))
  File "/home/imt/work/pyqt5-images-classifier/w3classifier/app/module.py", line 214, in get_label_value_on_image
    return {'imlabel': self.main.at[im, label]}
  File "/home/imt/.local/lib/python3.6/site-packages/pandas/core/indexing.py", line 2179, in __getitem__
    return self.obj._get_value(*key, takeable=self._takeable)
  File "/home/imt/.local/lib/python3.6/site-packages/pandas/core/frame.py", line 2919, in _get_value
    index = self.index.get_loc(index)
  File "/home/imt/.local/lib/python3.6/site-packages/pandas/core/indexes/base.py", line 2648, in get_loc
    return self._engine.get_loc(self._maybe_cast_indexer(key))
  File "pandas/_libs/index.pyx", line 111, in pandas._libs.index.IndexEngine.get_loc
  File "pandas/_libs/index.pyx", line 138, in pandas._libs.index.IndexEngine.get_loc
  File "pandas/_libs/hashtable_class_helper.pxi", line 1619, in pandas._libs.hashtable.PyObjectHashTable.get_item
  File "pandas/_libs/hashtable_class_helper.pxi", line 1627, in pandas._libs.hashtable.PyObjectHashTable.get_item
KeyError: 'undefined'
[2020-09-14 21:42:22,056][werkzeug][INFO] - 127.0.0.1 - - [14/Sep/2020 21:42:22] "[35m[1mGET /get_label_value_on_image/person/undefined HTTP/1.1[0m" 500 -
[2020-09-14 21:42:22,425][werkzeug][INFO] - 127.0.0.1 - - [14/Sep/2020 21:42:22] "[37mGET /set_filter/none/all/person/yes/none HTTP/1.1[0m" 200 -
[2020-09-14 21:42:22,427][w3classifier.app][ERROR] - Exception on /get_label_value_on_image/person/undefined [GET]
Traceback (most recent call last):
  File "/home/imt/.local/lib/python3.6/site-packages/pandas/core/indexes/base.py", line 2646, in get_loc
    return self._engine.get_loc(key)
  File "pandas/_libs/index.pyx", line 111, in pandas._libs.index.IndexEngine.get_loc
  File "pandas/_libs/index.pyx", line 138, in pandas._libs.index.IndexEngine.get_loc
  File "pandas/_libs/hashtable_class_helper.pxi", line 1619, in pandas._libs.hashtable.PyObjectHashTable.get_item
  File "pandas/_libs/hashtable_class_helper.pxi", line 1627, in pandas._libs.hashtable.PyObjectHashTable.get_item
KeyError: 'undefined'

During handling of the above exception, another exception occurred:

Traceback (most recent call last):
  File "/usr/local/lib/python3.6/dist-packages/flask/app.py", line 2447, in wsgi_app
    response = self.full_dispatch_request()
  File "/usr/local/lib/python3.6/dist-packages/flask/app.py", line 1952, in full_dispatch_request
    rv = self.handle_user_exception(e)
  File "/usr/local/lib/python3.6/dist-packages/flask_cors/extension.py", line 161, in wrapped_function
    return cors_after_request(app.make_response(f(*args, **kwargs)))
  File "/usr/local/lib/python3.6/dist-packages/flask/app.py", line 1821, in handle_user_exception
    reraise(exc_type, exc_value, tb)
  File "/usr/local/lib/python3.6/dist-packages/flask/_compat.py", line 39, in reraise
    raise value
  File "/usr/local/lib/python3.6/dist-packages/flask/app.py", line 1950, in full_dispatch_request
    rv = self.dispatch_request()
  File "/usr/local/lib/python3.6/dist-packages/flask/app.py", line 1936, in dispatch_request
    return self.view_functions[rule.endpoint](**req.view_args)
  File "/home/imt/work/pyqt5-images-classifier/w3classifier/app/views.py", line 59, in get_label_value_on_image
    return jsonify(dbs.get_label_value_on_image(label, im))
  File "/home/imt/work/pyqt5-images-classifier/w3classifier/app/module.py", line 214, in get_label_value_on_image
    return {'imlabel': self.main.at[im, label]}
  File "/home/imt/.local/lib/python3.6/site-packages/pandas/core/indexing.py", line 2179, in __getitem__
    return self.obj._get_value(*key, takeable=self._takeable)
  File "/home/imt/.local/lib/python3.6/site-packages/pandas/core/frame.py", line 2919, in _get_value
    index = self.index.get_loc(index)
  File "/home/imt/.local/lib/python3.6/site-packages/pandas/core/indexes/base.py", line 2648, in get_loc
    return self._engine.get_loc(self._maybe_cast_indexer(key))
  File "pandas/_libs/index.pyx", line 111, in pandas._libs.index.IndexEngine.get_loc
  File "pandas/_libs/index.pyx", line 138, in pandas._libs.index.IndexEngine.get_loc
  File "pandas/_libs/hashtable_class_helper.pxi", line 1619, in pandas._libs.hashtable.PyObjectHashTable.get_item
  File "pandas/_libs/hashtable_class_helper.pxi", line 1627, in pandas._libs.hashtable.PyObjectHashTable.get_item
KeyError: 'undefined'
[2020-09-14 21:42:22,428][werkzeug][INFO] - 127.0.0.1 - - [14/Sep/2020 21:42:22] "[35m[1mGET /get_label_value_on_image/person/undefined HTTP/1.1[0m" 500 -
[2020-09-14 21:42:22,886][werkzeug][INFO] - 127.0.0.1 - - [14/Sep/2020 21:42:22] "[37mGET /set_filter/none/all/person/yes/none HTTP/1.1[0m" 200 -
[2020-09-14 21:42:22,889][w3classifier.app][ERROR] - Exception on /get_label_value_on_image/person/undefined [GET]
Traceback (most recent call last):
  File "/home/imt/.local/lib/python3.6/site-packages/pandas/core/indexes/base.py", line 2646, in get_loc
    return self._engine.get_loc(key)
  File "pandas/_libs/index.pyx", line 111, in pandas._libs.index.IndexEngine.get_loc
  File "pandas/_libs/index.pyx", line 138, in pandas._libs.index.IndexEngine.get_loc
  File "pandas/_libs/hashtable_class_helper.pxi", line 1619, in pandas._libs.hashtable.PyObjectHashTable.get_item
  File "pandas/_libs/hashtable_class_helper.pxi", line 1627, in pandas._libs.hashtable.PyObjectHashTable.get_item
KeyError: 'undefined'

During handling of the above exception, another exception occurred:

Traceback (most recent call last):
  File "/usr/local/lib/python3.6/dist-packages/flask/app.py", line 2447, in wsgi_app
    response = self.full_dispatch_request()
  File "/usr/local/lib/python3.6/dist-packages/flask/app.py", line 1952, in full_dispatch_request
    rv = self.handle_user_exception(e)
  File "/usr/local/lib/python3.6/dist-packages/flask_cors/extension.py", line 161, in wrapped_function
    return cors_after_request(app.make_response(f(*args, **kwargs)))
  File "/usr/local/lib/python3.6/dist-packages/flask/app.py", line 1821, in handle_user_exception
    reraise(exc_type, exc_value, tb)
  File "/usr/local/lib/python3.6/dist-packages/flask/_compat.py", line 39, in reraise
    raise value
  File "/usr/local/lib/python3.6/dist-packages/flask/app.py", line 1950, in full_dispatch_request
    rv = self.dispatch_request()
  File "/usr/local/lib/python3.6/dist-packages/flask/app.py", line 1936, in dispatch_request
    return self.view_functions[rule.endpoint](**req.view_args)
  File "/home/imt/work/pyqt5-images-classifier/w3classifier/app/views.py", line 59, in get_label_value_on_image
    return jsonify(dbs.get_label_value_on_image(label, im))
  File "/home/imt/work/pyqt5-images-classifier/w3classifier/app/module.py", line 214, in get_label_value_on_image
    return {'imlabel': self.main.at[im, label]}
  File "/home/imt/.local/lib/python3.6/site-packages/pandas/core/indexing.py", line 2179, in __getitem__
    return self.obj._get_value(*key, takeable=self._takeable)
  File "/home/imt/.local/lib/python3.6/site-packages/pandas/core/frame.py", line 2919, in _get_value
    index = self.index.get_loc(index)
  File "/home/imt/.local/lib/python3.6/site-packages/pandas/core/indexes/base.py", line 2648, in get_loc
    return self._engine.get_loc(self._maybe_cast_indexer(key))
  File "pandas/_libs/index.pyx", line 111, in pandas._libs.index.IndexEngine.get_loc
  File "pandas/_libs/index.pyx", line 138, in pandas._libs.index.IndexEngine.get_loc
  File "pandas/_libs/hashtable_class_helper.pxi", line 1619, in pandas._libs.hashtable.PyObjectHashTable.get_item
  File "pandas/_libs/hashtable_class_helper.pxi", line 1627, in pandas._libs.hashtable.PyObjectHashTable.get_item
KeyError: 'undefined'
[2020-09-14 21:42:22,890][werkzeug][INFO] - 127.0.0.1 - - [14/Sep/2020 21:42:22] "[35m[1mGET /get_label_value_on_image/person/undefined HTTP/1.1[0m" 500 -
[2020-09-14 21:44:05,625][werkzeug][INFO] - 127.0.0.1 - - [14/Sep/2020 21:44:05] "[37mGET /marked_image/undefined HTTP/1.1[0m" 200 -
[2020-09-14 21:44:05,643][werkzeug][INFO] - 127.0.0.1 - - [14/Sep/2020 21:44:05] "[37mGET /set_filter/none/all/none/no/none HTTP/1.1[0m" 200 -
[2020-09-14 21:44:05,668][werkzeug][INFO] - 127.0.0.1 - - [14/Sep/2020 21:44:05] "[37mGET /get_label_value_on_image/none/0103_15_07_56_i4981_id276_cn1578064077907896000_thr540.In%20.jpg HTTP/1.1[0m" 200 -
[2020-09-14 21:44:05,671][werkzeug][INFO] - 127.0.0.1 - - [14/Sep/2020 21:44:05] "[37mGET /marked_image/0103_15_07_56_i4981_id276_cn1578064077907896000_thr540.In%20.jpg HTTP/1.1[0m" 200 -
[2020-09-14 21:44:15,772][werkzeug][INFO] - 127.0.0.1 - - [14/Sep/2020 21:44:15] "[37mGET /set_filter/none/all/none/yes/none HTTP/1.1[0m" 200 -
[2020-09-14 21:44:15,802][werkzeug][INFO] - 127.0.0.1 - - [14/Sep/2020 21:44:15] "[37mGET /get_label_value_on_image/none/0103_15_07_56_i4981_id276_cn1578064077907896000_thr540.In%20.jpg HTTP/1.1[0m" 200 -
[2020-09-14 21:44:16,895][werkzeug][INFO] - 127.0.0.1 - - [14/Sep/2020 21:44:16] "[37mGET /set_filter/none/all/person/yes/none HTTP/1.1[0m" 200 -
[2020-09-14 21:44:16,899][w3classifier.app][ERROR] - Exception on /get_label_value_on_image/person/undefined [GET]
Traceback (most recent call last):
  File "/home/imt/.local/lib/python3.6/site-packages/pandas/core/indexes/base.py", line 2646, in get_loc
    return self._engine.get_loc(key)
  File "pandas/_libs/index.pyx", line 111, in pandas._libs.index.IndexEngine.get_loc
  File "pandas/_libs/index.pyx", line 138, in pandas._libs.index.IndexEngine.get_loc
  File "pandas/_libs/hashtable_class_helper.pxi", line 1619, in pandas._libs.hashtable.PyObjectHashTable.get_item
  File "pandas/_libs/hashtable_class_helper.pxi", line 1627, in pandas._libs.hashtable.PyObjectHashTable.get_item
KeyError: 'undefined'

During handling of the above exception, another exception occurred:

Traceback (most recent call last):
  File "/usr/local/lib/python3.6/dist-packages/flask/app.py", line 2447, in wsgi_app
    response = self.full_dispatch_request()
  File "/usr/local/lib/python3.6/dist-packages/flask/app.py", line 1952, in full_dispatch_request
    rv = self.handle_user_exception(e)
  File "/usr/local/lib/python3.6/dist-packages/flask_cors/extension.py", line 161, in wrapped_function
    return cors_after_request(app.make_response(f(*args, **kwargs)))
  File "/usr/local/lib/python3.6/dist-packages/flask/app.py", line 1821, in handle_user_exception
    reraise(exc_type, exc_value, tb)
  File "/usr/local/lib/python3.6/dist-packages/flask/_compat.py", line 39, in reraise
    raise value
  File "/usr/local/lib/python3.6/dist-packages/flask/app.py", line 1950, in full_dispatch_request
    rv = self.dispatch_request()
  File "/usr/local/lib/python3.6/dist-packages/flask/app.py", line 1936, in dispatch_request
    return self.view_functions[rule.endpoint](**req.view_args)
  File "/home/imt/work/pyqt5-images-classifier/w3classifier/app/views.py", line 59, in get_label_value_on_image
    return jsonify(dbs.get_label_value_on_image(label, im))
  File "/home/imt/work/pyqt5-images-classifier/w3classifier/app/module.py", line 214, in get_label_value_on_image
    return {'imlabel': self.main.at[im, label]}
  File "/home/imt/.local/lib/python3.6/site-packages/pandas/core/indexing.py", line 2179, in __getitem__
    return self.obj._get_value(*key, takeable=self._takeable)
  File "/home/imt/.local/lib/python3.6/site-packages/pandas/core/frame.py", line 2919, in _get_value
    index = self.index.get_loc(index)
  File "/home/imt/.local/lib/python3.6/site-packages/pandas/core/indexes/base.py", line 2648, in get_loc
    return self._engine.get_loc(self._maybe_cast_indexer(key))
  File "pandas/_libs/index.pyx", line 111, in pandas._libs.index.IndexEngine.get_loc
  File "pandas/_libs/index.pyx", line 138, in pandas._libs.index.IndexEngine.get_loc
  File "pandas/_libs/hashtable_class_helper.pxi", line 1619, in pandas._libs.hashtable.PyObjectHashTable.get_item
  File "pandas/_libs/hashtable_class_helper.pxi", line 1627, in pandas._libs.hashtable.PyObjectHashTable.get_item
KeyError: 'undefined'
[2020-09-14 21:44:16,899][werkzeug][INFO] - 127.0.0.1 - - [14/Sep/2020 21:44:16] "[35m[1mGET /get_label_value_on_image/person/undefined HTTP/1.1[0m" 500 -
[2020-09-14 21:44:16,901][werkzeug][INFO] - 127.0.0.1 - - [14/Sep/2020 21:44:16] "[37mGET /marked_image/undefined HTTP/1.1[0m" 200 -
[2020-09-14 21:44:18,255][werkzeug][INFO] - 127.0.0.1 - - [14/Sep/2020 21:44:18] "[37mGET /set_filter/none/all/person/yes/none HTTP/1.1[0m" 200 -
[2020-09-14 21:44:18,258][w3classifier.app][ERROR] - Exception on /get_label_value_on_image/person/undefined [GET]
Traceback (most recent call last):
  File "/home/imt/.local/lib/python3.6/site-packages/pandas/core/indexes/base.py", line 2646, in get_loc
    return self._engine.get_loc(key)
  File "pandas/_libs/index.pyx", line 111, in pandas._libs.index.IndexEngine.get_loc
  File "pandas/_libs/index.pyx", line 138, in pandas._libs.index.IndexEngine.get_loc
  File "pandas/_libs/hashtable_class_helper.pxi", line 1619, in pandas._libs.hashtable.PyObjectHashTable.get_item
  File "pandas/_libs/hashtable_class_helper.pxi", line 1627, in pandas._libs.hashtable.PyObjectHashTable.get_item
KeyError: 'undefined'

During handling of the above exception, another exception occurred:

Traceback (most recent call last):
  File "/usr/local/lib/python3.6/dist-packages/flask/app.py", line 2447, in wsgi_app
    response = self.full_dispatch_request()
  File "/usr/local/lib/python3.6/dist-packages/flask/app.py", line 1952, in full_dispatch_request
    rv = self.handle_user_exception(e)
  File "/usr/local/lib/python3.6/dist-packages/flask_cors/extension.py", line 161, in wrapped_function
    return cors_after_request(app.make_response(f(*args, **kwargs)))
  File "/usr/local/lib/python3.6/dist-packages/flask/app.py", line 1821, in handle_user_exception
    reraise(exc_type, exc_value, tb)
  File "/usr/local/lib/python3.6/dist-packages/flask/_compat.py", line 39, in reraise
    raise value
  File "/usr/local/lib/python3.6/dist-packages/flask/app.py", line 1950, in full_dispatch_request
    rv = self.dispatch_request()
  File "/usr/local/lib/python3.6/dist-packages/flask/app.py", line 1936, in dispatch_request
    return self.view_functions[rule.endpoint](**req.view_args)
  File "/home/imt/work/pyqt5-images-classifier/w3classifier/app/views.py", line 59, in get_label_value_on_image
    return jsonify(dbs.get_label_value_on_image(label, im))
  File "/home/imt/work/pyqt5-images-classifier/w3classifier/app/module.py", line 214, in get_label_value_on_image
    return {'imlabel': self.main.at[im, label]}
  File "/home/imt/.local/lib/python3.6/site-packages/pandas/core/indexing.py", line 2179, in __getitem__
    return self.obj._get_value(*key, takeable=self._takeable)
  File "/home/imt/.local/lib/python3.6/site-packages/pandas/core/frame.py", line 2919, in _get_value
    index = self.index.get_loc(index)
  File "/home/imt/.local/lib/python3.6/site-packages/pandas/core/indexes/base.py", line 2648, in get_loc
    return self._engine.get_loc(self._maybe_cast_indexer(key))
  File "pandas/_libs/index.pyx", line 111, in pandas._libs.index.IndexEngine.get_loc
  File "pandas/_libs/index.pyx", line 138, in pandas._libs.index.IndexEngine.get_loc
  File "pandas/_libs/hashtable_class_helper.pxi", line 1619, in pandas._libs.hashtable.PyObjectHashTable.get_item
  File "pandas/_libs/hashtable_class_helper.pxi", line 1627, in pandas._libs.hashtable.PyObjectHashTable.get_item
KeyError: 'undefined'
[2020-09-14 21:44:18,259][werkzeug][INFO] - 127.0.0.1 - - [14/Sep/2020 21:44:18] "[35m[1mGET /get_label_value_on_image/person/undefined HTTP/1.1[0m" 500 -
[2020-09-14 21:45:16,126][werkzeug][INFO] - 127.0.0.1 - - [14/Sep/2020 21:45:16] "[37mGET /marked_image/undefined HTTP/1.1[0m" 200 -
[2020-09-14 21:45:16,144][werkzeug][INFO] - 127.0.0.1 - - [14/Sep/2020 21:45:16] "[37mGET /set_filter/none/all/none/no/none HTTP/1.1[0m" 200 -
[2020-09-14 21:45:16,175][werkzeug][INFO] - 127.0.0.1 - - [14/Sep/2020 21:45:16] "[37mGET /get_label_value_on_image/none/0103_15_07_56_i4981_id276_cn1578064077907896000_thr540.In%20.jpg HTTP/1.1[0m" 200 -
[2020-09-14 21:45:16,177][werkzeug][INFO] - 127.0.0.1 - - [14/Sep/2020 21:45:16] "[37mGET /marked_image/0103_15_07_56_i4981_id276_cn1578064077907896000_thr540.In%20.jpg HTTP/1.1[0m" 200 -
[2020-09-14 21:45:22,151][werkzeug][INFO] - 127.0.0.1 - - [14/Sep/2020 21:45:22] "[37mGET /set_filter/none/all/person/no/none HTTP/1.1[0m" 200 -
[2020-09-14 21:45:22,173][werkzeug][INFO] - 127.0.0.1 - - [14/Sep/2020 21:45:22] "[37mGET /get_label_value_on_image/person/0103_15_07_56_i4981_id276_cn1578064077907896000_thr540.In%20.jpg HTTP/1.1[0m" 200 -
[2020-09-14 21:45:23,240][werkzeug][INFO] - 127.0.0.1 - - [14/Sep/2020 21:45:23] "[37mGET /set_filter/none/all/person/yes/none HTTP/1.1[0m" 200 -
[2020-09-14 21:45:23,243][w3classifier.app][ERROR] - Exception on /get_label_value_on_image/person/undefined [GET]
Traceback (most recent call last):
  File "/home/imt/.local/lib/python3.6/site-packages/pandas/core/indexes/base.py", line 2646, in get_loc
    return self._engine.get_loc(key)
  File "pandas/_libs/index.pyx", line 111, in pandas._libs.index.IndexEngine.get_loc
  File "pandas/_libs/index.pyx", line 138, in pandas._libs.index.IndexEngine.get_loc
  File "pandas/_libs/hashtable_class_helper.pxi", line 1619, in pandas._libs.hashtable.PyObjectHashTable.get_item
  File "pandas/_libs/hashtable_class_helper.pxi", line 1627, in pandas._libs.hashtable.PyObjectHashTable.get_item
KeyError: 'undefined'

During handling of the above exception, another exception occurred:

Traceback (most recent call last):
  File "/usr/local/lib/python3.6/dist-packages/flask/app.py", line 2447, in wsgi_app
    response = self.full_dispatch_request()
  File "/usr/local/lib/python3.6/dist-packages/flask/app.py", line 1952, in full_dispatch_request
    rv = self.handle_user_exception(e)
  File "/usr/local/lib/python3.6/dist-packages/flask_cors/extension.py", line 161, in wrapped_function
    return cors_after_request(app.make_response(f(*args, **kwargs)))
  File "/usr/local/lib/python3.6/dist-packages/flask/app.py", line 1821, in handle_user_exception
    reraise(exc_type, exc_value, tb)
  File "/usr/local/lib/python3.6/dist-packages/flask/_compat.py", line 39, in reraise
    raise value
  File "/usr/local/lib/python3.6/dist-packages/flask/app.py", line 1950, in full_dispatch_request
    rv = self.dispatch_request()
  File "/usr/local/lib/python3.6/dist-packages/flask/app.py", line 1936, in dispatch_request
    return self.view_functions[rule.endpoint](**req.view_args)
  File "/home/imt/work/pyqt5-images-classifier/w3classifier/app/views.py", line 59, in get_label_value_on_image
    return jsonify(dbs.get_label_value_on_image(label, im))
  File "/home/imt/work/pyqt5-images-classifier/w3classifier/app/module.py", line 214, in get_label_value_on_image
    return {'imlabel': self.main.at[im, label]}
  File "/home/imt/.local/lib/python3.6/site-packages/pandas/core/indexing.py", line 2179, in __getitem__
    return self.obj._get_value(*key, takeable=self._takeable)
  File "/home/imt/.local/lib/python3.6/site-packages/pandas/core/frame.py", line 2919, in _get_value
    index = self.index.get_loc(index)
  File "/home/imt/.local/lib/python3.6/site-packages/pandas/core/indexes/base.py", line 2648, in get_loc
    return self._engine.get_loc(self._maybe_cast_indexer(key))
  File "pandas/_libs/index.pyx", line 111, in pandas._libs.index.IndexEngine.get_loc
  File "pandas/_libs/index.pyx", line 138, in pandas._libs.index.IndexEngine.get_loc
  File "pandas/_libs/hashtable_class_helper.pxi", line 1619, in pandas._libs.hashtable.PyObjectHashTable.get_item
  File "pandas/_libs/hashtable_class_helper.pxi", line 1627, in pandas._libs.hashtable.PyObjectHashTable.get_item
KeyError: 'undefined'
[2020-09-14 21:45:23,244][werkzeug][INFO] - 127.0.0.1 - - [14/Sep/2020 21:45:23] "[37mGET /marked_image/undefined HTTP/1.1[0m" 200 -
[2020-09-14 21:45:23,245][werkzeug][INFO] - 127.0.0.1 - - [14/Sep/2020 21:45:23] "[35m[1mGET /get_label_value_on_image/person/undefined HTTP/1.1[0m" 500 -
[2020-09-14 21:45:24,412][werkzeug][INFO] - 127.0.0.1 - - [14/Sep/2020 21:45:24] "[37mGET /set_filter/none/all/person/yes/none HTTP/1.1[0m" 200 -
[2020-09-14 21:45:24,415][w3classifier.app][ERROR] - Exception on /get_label_value_on_image/person/undefined [GET]
Traceback (most recent call last):
  File "/home/imt/.local/lib/python3.6/site-packages/pandas/core/indexes/base.py", line 2646, in get_loc
    return self._engine.get_loc(key)
  File "pandas/_libs/index.pyx", line 111, in pandas._libs.index.IndexEngine.get_loc
  File "pandas/_libs/index.pyx", line 138, in pandas._libs.index.IndexEngine.get_loc
  File "pandas/_libs/hashtable_class_helper.pxi", line 1619, in pandas._libs.hashtable.PyObjectHashTable.get_item
  File "pandas/_libs/hashtable_class_helper.pxi", line 1627, in pandas._libs.hashtable.PyObjectHashTable.get_item
KeyError: 'undefined'

During handling of the above exception, another exception occurred:

Traceback (most recent call last):
  File "/usr/local/lib/python3.6/dist-packages/flask/app.py", line 2447, in wsgi_app
    response = self.full_dispatch_request()
  File "/usr/local/lib/python3.6/dist-packages/flask/app.py", line 1952, in full_dispatch_request
    rv = self.handle_user_exception(e)
  File "/usr/local/lib/python3.6/dist-packages/flask_cors/extension.py", line 161, in wrapped_function
    return cors_after_request(app.make_response(f(*args, **kwargs)))
  File "/usr/local/lib/python3.6/dist-packages/flask/app.py", line 1821, in handle_user_exception
    reraise(exc_type, exc_value, tb)
  File "/usr/local/lib/python3.6/dist-packages/flask/_compat.py", line 39, in reraise
    raise value
  File "/usr/local/lib/python3.6/dist-packages/flask/app.py", line 1950, in full_dispatch_request
    rv = self.dispatch_request()
  File "/usr/local/lib/python3.6/dist-packages/flask/app.py", line 1936, in dispatch_request
    return self.view_functions[rule.endpoint](**req.view_args)
  File "/home/imt/work/pyqt5-images-classifier/w3classifier/app/views.py", line 59, in get_label_value_on_image
    return jsonify(dbs.get_label_value_on_image(label, im))
  File "/home/imt/work/pyqt5-images-classifier/w3classifier/app/module.py", line 214, in get_label_value_on_image
    return {'imlabel': self.main.at[im, label]}
  File "/home/imt/.local/lib/python3.6/site-packages/pandas/core/indexing.py", line 2179, in __getitem__
    return self.obj._get_value(*key, takeable=self._takeable)
  File "/home/imt/.local/lib/python3.6/site-packages/pandas/core/frame.py", line 2919, in _get_value
    index = self.index.get_loc(index)
  File "/home/imt/.local/lib/python3.6/site-packages/pandas/core/indexes/base.py", line 2648, in get_loc
    return self._engine.get_loc(self._maybe_cast_indexer(key))
  File "pandas/_libs/index.pyx", line 111, in pandas._libs.index.IndexEngine.get_loc
  File "pandas/_libs/index.pyx", line 138, in pandas._libs.index.IndexEngine.get_loc
  File "pandas/_libs/hashtable_class_helper.pxi", line 1619, in pandas._libs.hashtable.PyObjectHashTable.get_item
  File "pandas/_libs/hashtable_class_helper.pxi", line 1627, in pandas._libs.hashtable.PyObjectHashTable.get_item
KeyError: 'undefined'
[2020-09-14 21:45:24,416][werkzeug][INFO] - 127.0.0.1 - - [14/Sep/2020 21:45:24] "[35m[1mGET /get_label_value_on_image/person/undefined HTTP/1.1[0m" 500 -
[2020-09-14 21:45:36,799][werkzeug][INFO] - 127.0.0.1 - - [14/Sep/2020 21:45:36] "[37mGET /set_filter/none/all/person/yes/none HTTP/1.1[0m" 200 -
[2020-09-14 21:45:36,802][w3classifier.app][ERROR] - Exception on /get_label_value_on_image/person/undefined [GET]
Traceback (most recent call last):
  File "/home/imt/.local/lib/python3.6/site-packages/pandas/core/indexes/base.py", line 2646, in get_loc
    return self._engine.get_loc(key)
  File "pandas/_libs/index.pyx", line 111, in pandas._libs.index.IndexEngine.get_loc
  File "pandas/_libs/index.pyx", line 138, in pandas._libs.index.IndexEngine.get_loc
  File "pandas/_libs/hashtable_class_helper.pxi", line 1619, in pandas._libs.hashtable.PyObjectHashTable.get_item
  File "pandas/_libs/hashtable_class_helper.pxi", line 1627, in pandas._libs.hashtable.PyObjectHashTable.get_item
KeyError: 'undefined'

During handling of the above exception, another exception occurred:

Traceback (most recent call last):
  File "/usr/local/lib/python3.6/dist-packages/flask/app.py", line 2447, in wsgi_app
    response = self.full_dispatch_request()
  File "/usr/local/lib/python3.6/dist-packages/flask/app.py", line 1952, in full_dispatch_request
    rv = self.handle_user_exception(e)
  File "/usr/local/lib/python3.6/dist-packages/flask_cors/extension.py", line 161, in wrapped_function
    return cors_after_request(app.make_response(f(*args, **kwargs)))
  File "/usr/local/lib/python3.6/dist-packages/flask/app.py", line 1821, in handle_user_exception
    reraise(exc_type, exc_value, tb)
  File "/usr/local/lib/python3.6/dist-packages/flask/_compat.py", line 39, in reraise
    raise value
  File "/usr/local/lib/python3.6/dist-packages/flask/app.py", line 1950, in full_dispatch_request
    rv = self.dispatch_request()
  File "/usr/local/lib/python3.6/dist-packages/flask/app.py", line 1936, in dispatch_request
    return self.view_functions[rule.endpoint](**req.view_args)
  File "/home/imt/work/pyqt5-images-classifier/w3classifier/app/views.py", line 59, in get_label_value_on_image
    return jsonify(dbs.get_label_value_on_image(label, im))
  File "/home/imt/work/pyqt5-images-classifier/w3classifier/app/module.py", line 214, in get_label_value_on_image
    return {'imlabel': self.main.at[im, label]}
  File "/home/imt/.local/lib/python3.6/site-packages/pandas/core/indexing.py", line 2179, in __getitem__
    return self.obj._get_value(*key, takeable=self._takeable)
  File "/home/imt/.local/lib/python3.6/site-packages/pandas/core/frame.py", line 2919, in _get_value
    index = self.index.get_loc(index)
  File "/home/imt/.local/lib/python3.6/site-packages/pandas/core/indexes/base.py", line 2648, in get_loc
    return self._engine.get_loc(self._maybe_cast_indexer(key))
  File "pandas/_libs/index.pyx", line 111, in pandas._libs.index.IndexEngine.get_loc
  File "pandas/_libs/index.pyx", line 138, in pandas._libs.index.IndexEngine.get_loc
  File "pandas/_libs/hashtable_class_helper.pxi", line 1619, in pandas._libs.hashtable.PyObjectHashTable.get_item
  File "pandas/_libs/hashtable_class_helper.pxi", line 1627, in pandas._libs.hashtable.PyObjectHashTable.get_item
KeyError: 'undefined'
[2020-09-14 21:45:36,802][werkzeug][INFO] - 127.0.0.1 - - [14/Sep/2020 21:45:36] "[35m[1mGET /get_label_value_on_image/person/undefined HTTP/1.1[0m" 500 -
[2020-09-14 21:46:16,207][werkzeug][INFO] - 127.0.0.1 - - [14/Sep/2020 21:46:16] "[37mGET /set_filter/none/all/none/no/none HTTP/1.1[0m" 200 -
[2020-09-14 21:46:16,208][werkzeug][INFO] - 127.0.0.1 - - [14/Sep/2020 21:46:16] "[37mGET /marked_image/undefined HTTP/1.1[0m" 200 -
[2020-09-14 21:46:16,234][werkzeug][INFO] - 127.0.0.1 - - [14/Sep/2020 21:46:16] "[37mGET /get_label_value_on_image/none/0103_15_07_56_i4981_id276_cn1578064077907896000_thr540.In%20.jpg HTTP/1.1[0m" 200 -
[2020-09-14 21:46:16,238][werkzeug][INFO] - 127.0.0.1 - - [14/Sep/2020 21:46:16] "[37mGET /marked_image/0103_15_07_56_i4981_id276_cn1578064077907896000_thr540.In%20.jpg HTTP/1.1[0m" 200 -
[2020-09-14 21:46:18,418][werkzeug][INFO] - 127.0.0.1 - - [14/Sep/2020 21:46:18] "[37mGET /set_filter/none/all/none/yes/none HTTP/1.1[0m" 200 -
[2020-09-14 21:46:18,453][werkzeug][INFO] - 127.0.0.1 - - [14/Sep/2020 21:46:18] "[37mGET /get_label_value_on_image/none/0103_15_07_56_i4981_id276_cn1578064077907896000_thr540.In%20.jpg HTTP/1.1[0m" 200 -
[2020-09-14 21:46:19,851][werkzeug][INFO] - 127.0.0.1 - - [14/Sep/2020 21:46:19] "[37mGET /set_filter/none/all/person/yes/none HTTP/1.1[0m" 200 -
[2020-09-14 21:46:19,854][w3classifier.app][ERROR] - Exception on /get_label_value_on_image/person/undefined [GET]
Traceback (most recent call last):
  File "/home/imt/.local/lib/python3.6/site-packages/pandas/core/indexes/base.py", line 2646, in get_loc
    return self._engine.get_loc(key)
  File "pandas/_libs/index.pyx", line 111, in pandas._libs.index.IndexEngine.get_loc
  File "pandas/_libs/index.pyx", line 138, in pandas._libs.index.IndexEngine.get_loc
  File "pandas/_libs/hashtable_class_helper.pxi", line 1619, in pandas._libs.hashtable.PyObjectHashTable.get_item
  File "pandas/_libs/hashtable_class_helper.pxi", line 1627, in pandas._libs.hashtable.PyObjectHashTable.get_item
KeyError: 'undefined'

During handling of the above exception, another exception occurred:

Traceback (most recent call last):
  File "/usr/local/lib/python3.6/dist-packages/flask/app.py", line 2447, in wsgi_app
    response = self.full_dispatch_request()
  File "/usr/local/lib/python3.6/dist-packages/flask/app.py", line 1952, in full_dispatch_request
    rv = self.handle_user_exception(e)
  File "/usr/local/lib/python3.6/dist-packages/flask_cors/extension.py", line 161, in wrapped_function
    return cors_after_request(app.make_response(f(*args, **kwargs)))
  File "/usr/local/lib/python3.6/dist-packages/flask/app.py", line 1821, in handle_user_exception
    reraise(exc_type, exc_value, tb)
  File "/usr/local/lib/python3.6/dist-packages/flask/_compat.py", line 39, in reraise
    raise value
  File "/usr/local/lib/python3.6/dist-packages/flask/app.py", line 1950, in full_dispatch_request
    rv = self.dispatch_request()
  File "/usr/local/lib/python3.6/dist-packages/flask/app.py", line 1936, in dispatch_request
    return self.view_functions[rule.endpoint](**req.view_args)
  File "/home/imt/work/pyqt5-images-classifier/w3classifier/app/views.py", line 59, in get_label_value_on_image
    return jsonify(dbs.get_label_value_on_image(label, im))
  File "/home/imt/work/pyqt5-images-classifier/w3classifier/app/module.py", line 214, in get_label_value_on_image
    return {'imlabel': self.main.at[im, label]}
  File "/home/imt/.local/lib/python3.6/site-packages/pandas/core/indexing.py", line 2179, in __getitem__
    return self.obj._get_value(*key, takeable=self._takeable)
  File "/home/imt/.local/lib/python3.6/site-packages/pandas/core/frame.py", line 2919, in _get_value
    index = self.index.get_loc(index)
  File "/home/imt/.local/lib/python3.6/site-packages/pandas/core/indexes/base.py", line 2648, in get_loc
    return self._engine.get_loc(self._maybe_cast_indexer(key))
  File "pandas/_libs/index.pyx", line 111, in pandas._libs.index.IndexEngine.get_loc
  File "pandas/_libs/index.pyx", line 138, in pandas._libs.index.IndexEngine.get_loc
  File "pandas/_libs/hashtable_class_helper.pxi", line 1619, in pandas._libs.hashtable.PyObjectHashTable.get_item
  File "pandas/_libs/hashtable_class_helper.pxi", line 1627, in pandas._libs.hashtable.PyObjectHashTable.get_item
KeyError: 'undefined'
[2020-09-14 21:46:19,855][werkzeug][INFO] - 127.0.0.1 - - [14/Sep/2020 21:46:19] "[35m[1mGET /get_label_value_on_image/person/undefined HTTP/1.1[0m" 500 -
[2020-09-14 21:46:19,857][werkzeug][INFO] - 127.0.0.1 - - [14/Sep/2020 21:46:19] "[37mGET /marked_image/undefined HTTP/1.1[0m" 200 -
[2020-09-14 21:46:20,799][werkzeug][INFO] - 127.0.0.1 - - [14/Sep/2020 21:46:20] "[37mGET /set_filter/none/all/person/yes/none HTTP/1.1[0m" 200 -
[2020-09-14 21:46:20,803][w3classifier.app][ERROR] - Exception on /get_label_value_on_image/person/undefined [GET]
Traceback (most recent call last):
  File "/home/imt/.local/lib/python3.6/site-packages/pandas/core/indexes/base.py", line 2646, in get_loc
    return self._engine.get_loc(key)
  File "pandas/_libs/index.pyx", line 111, in pandas._libs.index.IndexEngine.get_loc
  File "pandas/_libs/index.pyx", line 138, in pandas._libs.index.IndexEngine.get_loc
  File "pandas/_libs/hashtable_class_helper.pxi", line 1619, in pandas._libs.hashtable.PyObjectHashTable.get_item
  File "pandas/_libs/hashtable_class_helper.pxi", line 1627, in pandas._libs.hashtable.PyObjectHashTable.get_item
KeyError: 'undefined'

During handling of the above exception, another exception occurred:

Traceback (most recent call last):
  File "/usr/local/lib/python3.6/dist-packages/flask/app.py", line 2447, in wsgi_app
    response = self.full_dispatch_request()
  File "/usr/local/lib/python3.6/dist-packages/flask/app.py", line 1952, in full_dispatch_request
    rv = self.handle_user_exception(e)
  File "/usr/local/lib/python3.6/dist-packages/flask_cors/extension.py", line 161, in wrapped_function
    return cors_after_request(app.make_response(f(*args, **kwargs)))
  File "/usr/local/lib/python3.6/dist-packages/flask/app.py", line 1821, in handle_user_exception
    reraise(exc_type, exc_value, tb)
  File "/usr/local/lib/python3.6/dist-packages/flask/_compat.py", line 39, in reraise
    raise value
  File "/usr/local/lib/python3.6/dist-packages/flask/app.py", line 1950, in full_dispatch_request
    rv = self.dispatch_request()
  File "/usr/local/lib/python3.6/dist-packages/flask/app.py", line 1936, in dispatch_request
    return self.view_functions[rule.endpoint](**req.view_args)
  File "/home/imt/work/pyqt5-images-classifier/w3classifier/app/views.py", line 59, in get_label_value_on_image
    return jsonify(dbs.get_label_value_on_image(label, im))
  File "/home/imt/work/pyqt5-images-classifier/w3classifier/app/module.py", line 214, in get_label_value_on_image
    return {'imlabel': self.main.at[im, label]}
  File "/home/imt/.local/lib/python3.6/site-packages/pandas/core/indexing.py", line 2179, in __getitem__
    return self.obj._get_value(*key, takeable=self._takeable)
  File "/home/imt/.local/lib/python3.6/site-packages/pandas/core/frame.py", line 2919, in _get_value
    index = self.index.get_loc(index)
  File "/home/imt/.local/lib/python3.6/site-packages/pandas/core/indexes/base.py", line 2648, in get_loc
    return self._engine.get_loc(self._maybe_cast_indexer(key))
  File "pandas/_libs/index.pyx", line 111, in pandas._libs.index.IndexEngine.get_loc
  File "pandas/_libs/index.pyx", line 138, in pandas._libs.index.IndexEngine.get_loc
  File "pandas/_libs/hashtable_class_helper.pxi", line 1619, in pandas._libs.hashtable.PyObjectHashTable.get_item
  File "pandas/_libs/hashtable_class_helper.pxi", line 1627, in pandas._libs.hashtable.PyObjectHashTable.get_item
KeyError: 'undefined'
[2020-09-14 21:46:20,803][werkzeug][INFO] - 127.0.0.1 - - [14/Sep/2020 21:46:20] "[35m[1mGET /get_label_value_on_image/person/undefined HTTP/1.1[0m" 500 -
[2020-09-14 21:46:50,426][werkzeug][INFO] - 127.0.0.1 - - [14/Sep/2020 21:46:50] "[37mGET /marked_image/undefined HTTP/1.1[0m" 200 -
[2020-09-14 21:46:50,443][werkzeug][INFO] - 127.0.0.1 - - [14/Sep/2020 21:46:50] "[37mGET /set_filter/none/all/none/no/none HTTP/1.1[0m" 200 -
[2020-09-14 21:46:50,474][werkzeug][INFO] - 127.0.0.1 - - [14/Sep/2020 21:46:50] "[37mGET /get_label_value_on_image/none/0103_15_07_56_i4981_id276_cn1578064077907896000_thr540.In%20.jpg HTTP/1.1[0m" 200 -
[2020-09-14 21:46:50,477][werkzeug][INFO] - 127.0.0.1 - - [14/Sep/2020 21:46:50] "[37mGET /marked_image/0103_15_07_56_i4981_id276_cn1578064077907896000_thr540.In%20.jpg HTTP/1.1[0m" 200 -
[2020-09-14 21:46:57,423][werkzeug][INFO] - 127.0.0.1 - - [14/Sep/2020 21:46:57] "[37mGET /set_filter/none/all/person/no/none HTTP/1.1[0m" 200 -
[2020-09-14 21:46:57,468][werkzeug][INFO] - 127.0.0.1 - - [14/Sep/2020 21:46:57] "[37mGET /get_label_value_on_image/person/0103_15_07_56_i4981_id276_cn1578064077907896000_thr540.In%20.jpg HTTP/1.1[0m" 200 -
[2020-09-14 21:46:58,659][werkzeug][INFO] - 127.0.0.1 - - [14/Sep/2020 21:46:58] "[37mGET /set_filter/none/all/person/yes/none HTTP/1.1[0m" 200 -
[2020-09-14 21:46:58,662][w3classifier.app][ERROR] - Exception on /get_label_value_on_image/person/undefined [GET]
Traceback (most recent call last):
  File "/home/imt/.local/lib/python3.6/site-packages/pandas/core/indexes/base.py", line 2646, in get_loc
    return self._engine.get_loc(key)
  File "pandas/_libs/index.pyx", line 111, in pandas._libs.index.IndexEngine.get_loc
  File "pandas/_libs/index.pyx", line 138, in pandas._libs.index.IndexEngine.get_loc
  File "pandas/_libs/hashtable_class_helper.pxi", line 1619, in pandas._libs.hashtable.PyObjectHashTable.get_item
  File "pandas/_libs/hashtable_class_helper.pxi", line 1627, in pandas._libs.hashtable.PyObjectHashTable.get_item
KeyError: 'undefined'

During handling of the above exception, another exception occurred:

Traceback (most recent call last):
  File "/usr/local/lib/python3.6/dist-packages/flask/app.py", line 2447, in wsgi_app
    response = self.full_dispatch_request()
  File "/usr/local/lib/python3.6/dist-packages/flask/app.py", line 1952, in full_dispatch_request
    rv = self.handle_user_exception(e)
  File "/usr/local/lib/python3.6/dist-packages/flask_cors/extension.py", line 161, in wrapped_function
    return cors_after_request(app.make_response(f(*args, **kwargs)))
  File "/usr/local/lib/python3.6/dist-packages/flask/app.py", line 1821, in handle_user_exception
    reraise(exc_type, exc_value, tb)
  File "/usr/local/lib/python3.6/dist-packages/flask/_compat.py", line 39, in reraise
    raise value
  File "/usr/local/lib/python3.6/dist-packages/flask/app.py", line 1950, in full_dispatch_request
    rv = self.dispatch_request()
  File "/usr/local/lib/python3.6/dist-packages/flask/app.py", line 1936, in dispatch_request
    return self.view_functions[rule.endpoint](**req.view_args)
  File "/home/imt/work/pyqt5-images-classifier/w3classifier/app/views.py", line 59, in get_label_value_on_image
    return jsonify(dbs.get_label_value_on_image(label, im))
  File "/home/imt/work/pyqt5-images-classifier/w3classifier/app/module.py", line 214, in get_label_value_on_image
    return {'imlabel': self.main.at[im, label]}
  File "/home/imt/.local/lib/python3.6/site-packages/pandas/core/indexing.py", line 2179, in __getitem__
    return self.obj._get_value(*key, takeable=self._takeable)
  File "/home/imt/.local/lib/python3.6/site-packages/pandas/core/frame.py", line 2919, in _get_value
    index = self.index.get_loc(index)
  File "/home/imt/.local/lib/python3.6/site-packages/pandas/core/indexes/base.py", line 2648, in get_loc
    return self._engine.get_loc(self._maybe_cast_indexer(key))
  File "pandas/_libs/index.pyx", line 111, in pandas._libs.index.IndexEngine.get_loc
  File "pandas/_libs/index.pyx", line 138, in pandas._libs.index.IndexEngine.get_loc
  File "pandas/_libs/hashtable_class_helper.pxi", line 1619, in pandas._libs.hashtable.PyObjectHashTable.get_item
  File "pandas/_libs/hashtable_class_helper.pxi", line 1627, in pandas._libs.hashtable.PyObjectHashTable.get_item
KeyError: 'undefined'
[2020-09-14 21:46:58,664][werkzeug][INFO] - 127.0.0.1 - - [14/Sep/2020 21:46:58] "[37mGET /marked_image/undefined HTTP/1.1[0m" 200 -
[2020-09-14 21:46:58,665][werkzeug][INFO] - 127.0.0.1 - - [14/Sep/2020 21:46:58] "[35m[1mGET /get_label_value_on_image/person/undefined HTTP/1.1[0m" 500 -
[2020-09-14 21:47:25,853][werkzeug][INFO] - 127.0.0.1 - - [14/Sep/2020 21:47:25] "[37mGET /set_filter/none/all/l_carring/yes/none HTTP/1.1[0m" 200 -
[2020-09-14 21:47:25,929][werkzeug][INFO] - 127.0.0.1 - - [14/Sep/2020 21:47:25] "[37mGET /get_label_value_on_image/l_carring/0104_09_28_28_i665149_id7699_cn1578130108206525000_thr541.Out%20.jpg HTTP/1.1[0m" 200 -
[2020-09-14 21:47:25,975][werkzeug][INFO] - 127.0.0.1 - - [14/Sep/2020 21:47:25] "[37mGET /marked_image/0104_09_28_28_i665149_id7699_cn1578130108206525000_thr541.Out%20.jpg HTTP/1.1[0m" 200 -
[2020-09-14 21:47:26,850][werkzeug][INFO] - 127.0.0.1 - - [14/Sep/2020 21:47:26] "[37mGET /set_filter/none/all/person/yes/none HTTP/1.1[0m" 200 -
[2020-09-14 21:47:26,852][w3classifier.app][ERROR] - Exception on /get_label_value_on_image/person/undefined [GET]
Traceback (most recent call last):
  File "/home/imt/.local/lib/python3.6/site-packages/pandas/core/indexes/base.py", line 2646, in get_loc
    return self._engine.get_loc(key)
  File "pandas/_libs/index.pyx", line 111, in pandas._libs.index.IndexEngine.get_loc
  File "pandas/_libs/index.pyx", line 138, in pandas._libs.index.IndexEngine.get_loc
  File "pandas/_libs/hashtable_class_helper.pxi", line 1619, in pandas._libs.hashtable.PyObjectHashTable.get_item
  File "pandas/_libs/hashtable_class_helper.pxi", line 1627, in pandas._libs.hashtable.PyObjectHashTable.get_item
KeyError: 'undefined'

During handling of the above exception, another exception occurred:

Traceback (most recent call last):
  File "/usr/local/lib/python3.6/dist-packages/flask/app.py", line 2447, in wsgi_app
    response = self.full_dispatch_request()
  File "/usr/local/lib/python3.6/dist-packages/flask/app.py", line 1952, in full_dispatch_request
    rv = self.handle_user_exception(e)
  File "/usr/local/lib/python3.6/dist-packages/flask_cors/extension.py", line 161, in wrapped_function
    return cors_after_request(app.make_response(f(*args, **kwargs)))
  File "/usr/local/lib/python3.6/dist-packages/flask/app.py", line 1821, in handle_user_exception
    reraise(exc_type, exc_value, tb)
  File "/usr/local/lib/python3.6/dist-packages/flask/_compat.py", line 39, in reraise
    raise value
  File "/usr/local/lib/python3.6/dist-packages/flask/app.py", line 1950, in full_dispatch_request
    rv = self.dispatch_request()
  File "/usr/local/lib/python3.6/dist-packages/flask/app.py", line 1936, in dispatch_request
    return self.view_functions[rule.endpoint](**req.view_args)
  File "/home/imt/work/pyqt5-images-classifier/w3classifier/app/views.py", line 59, in get_label_value_on_image
    return jsonify(dbs.get_label_value_on_image(label, im))
  File "/home/imt/work/pyqt5-images-classifier/w3classifier/app/module.py", line 214, in get_label_value_on_image
    return {'imlabel': self.main.at[im, label]}
  File "/home/imt/.local/lib/python3.6/site-packages/pandas/core/indexing.py", line 2179, in __getitem__
    return self.obj._get_value(*key, takeable=self._takeable)
  File "/home/imt/.local/lib/python3.6/site-packages/pandas/core/frame.py", line 2919, in _get_value
    index = self.index.get_loc(index)
  File "/home/imt/.local/lib/python3.6/site-packages/pandas/core/indexes/base.py", line 2648, in get_loc
    return self._engine.get_loc(self._maybe_cast_indexer(key))
  File "pandas/_libs/index.pyx", line 111, in pandas._libs.index.IndexEngine.get_loc
  File "pandas/_libs/index.pyx", line 138, in pandas._libs.index.IndexEngine.get_loc
  File "pandas/_libs/hashtable_class_helper.pxi", line 1619, in pandas._libs.hashtable.PyObjectHashTable.get_item
  File "pandas/_libs/hashtable_class_helper.pxi", line 1627, in pandas._libs.hashtable.PyObjectHashTable.get_item
KeyError: 'undefined'
[2020-09-14 21:47:26,853][werkzeug][INFO] - 127.0.0.1 - - [14/Sep/2020 21:47:26] "[35m[1mGET /get_label_value_on_image/person/undefined HTTP/1.1[0m" 500 -
[2020-09-14 21:47:26,854][werkzeug][INFO] - 127.0.0.1 - - [14/Sep/2020 21:47:26] "[37mGET /marked_image/undefined HTTP/1.1[0m" 200 -
[2020-09-14 21:47:33,939][werkzeug][INFO] - 127.0.0.1 - - [14/Sep/2020 21:47:33] "[37mGET /set_filter/none/all/person/yes/none HTTP/1.1[0m" 200 -
[2020-09-14 21:47:33,943][w3classifier.app][ERROR] - Exception on /get_label_value_on_image/person/undefined [GET]
Traceback (most recent call last):
  File "/home/imt/.local/lib/python3.6/site-packages/pandas/core/indexes/base.py", line 2646, in get_loc
    return self._engine.get_loc(key)
  File "pandas/_libs/index.pyx", line 111, in pandas._libs.index.IndexEngine.get_loc
  File "pandas/_libs/index.pyx", line 138, in pandas._libs.index.IndexEngine.get_loc
  File "pandas/_libs/hashtable_class_helper.pxi", line 1619, in pandas._libs.hashtable.PyObjectHashTable.get_item
  File "pandas/_libs/hashtable_class_helper.pxi", line 1627, in pandas._libs.hashtable.PyObjectHashTable.get_item
KeyError: 'undefined'

During handling of the above exception, another exception occurred:

Traceback (most recent call last):
  File "/usr/local/lib/python3.6/dist-packages/flask/app.py", line 2447, in wsgi_app
    response = self.full_dispatch_request()
  File "/usr/local/lib/python3.6/dist-packages/flask/app.py", line 1952, in full_dispatch_request
    rv = self.handle_user_exception(e)
  File "/usr/local/lib/python3.6/dist-packages/flask_cors/extension.py", line 161, in wrapped_function
    return cors_after_request(app.make_response(f(*args, **kwargs)))
  File "/usr/local/lib/python3.6/dist-packages/flask/app.py", line 1821, in handle_user_exception
    reraise(exc_type, exc_value, tb)
  File "/usr/local/lib/python3.6/dist-packages/flask/_compat.py", line 39, in reraise
    raise value
  File "/usr/local/lib/python3.6/dist-packages/flask/app.py", line 1950, in full_dispatch_request
    rv = self.dispatch_request()
  File "/usr/local/lib/python3.6/dist-packages/flask/app.py", line 1936, in dispatch_request
    return self.view_functions[rule.endpoint](**req.view_args)
  File "/home/imt/work/pyqt5-images-classifier/w3classifier/app/views.py", line 59, in get_label_value_on_image
    return jsonify(dbs.get_label_value_on_image(label, im))
  File "/home/imt/work/pyqt5-images-classifier/w3classifier/app/module.py", line 214, in get_label_value_on_image
    return {'imlabel': self.main.at[im, label]}
  File "/home/imt/.local/lib/python3.6/site-packages/pandas/core/indexing.py", line 2179, in __getitem__
    return self.obj._get_value(*key, takeable=self._takeable)
  File "/home/imt/.local/lib/python3.6/site-packages/pandas/core/frame.py", line 2919, in _get_value
    index = self.index.get_loc(index)
  File "/home/imt/.local/lib/python3.6/site-packages/pandas/core/indexes/base.py", line 2648, in get_loc
    return self._engine.get_loc(self._maybe_cast_indexer(key))
  File "pandas/_libs/index.pyx", line 111, in pandas._libs.index.IndexEngine.get_loc
  File "pandas/_libs/index.pyx", line 138, in pandas._libs.index.IndexEngine.get_loc
  File "pandas/_libs/hashtable_class_helper.pxi", line 1619, in pandas._libs.hashtable.PyObjectHashTable.get_item
  File "pandas/_libs/hashtable_class_helper.pxi", line 1627, in pandas._libs.hashtable.PyObjectHashTable.get_item
KeyError: 'undefined'
[2020-09-14 21:47:33,943][werkzeug][INFO] - 127.0.0.1 - - [14/Sep/2020 21:47:33] "[35m[1mGET /get_label_value_on_image/person/undefined HTTP/1.1[0m" 500 -
[2020-09-14 21:48:14,104][werkzeug][INFO] - 127.0.0.1 - - [14/Sep/2020 21:48:14] "[37mGET /marked_image/undefined HTTP/1.1[0m" 200 -
[2020-09-14 21:48:14,131][werkzeug][INFO] - 127.0.0.1 - - [14/Sep/2020 21:48:14] "[37mGET /set_filter/none/all/none/no/none HTTP/1.1[0m" 200 -
[2020-09-14 21:48:14,167][werkzeug][INFO] - 127.0.0.1 - - [14/Sep/2020 21:48:14] "[37mGET /get_label_value_on_image/none/0103_15_07_56_i4981_id276_cn1578064077907896000_thr540.In%20.jpg HTTP/1.1[0m" 200 -
[2020-09-14 21:48:14,172][werkzeug][INFO] - 127.0.0.1 - - [14/Sep/2020 21:48:14] "[37mGET /marked_image/0103_15_07_56_i4981_id276_cn1578064077907896000_thr540.In%20.jpg HTTP/1.1[0m" 200 -
[2020-09-14 21:48:47,576][werkzeug][INFO] - 127.0.0.1 - - [14/Sep/2020 21:48:47] "[37mGET /marked_image/undefined HTTP/1.1[0m" 200 -
[2020-09-14 21:48:47,599][werkzeug][INFO] - 127.0.0.1 - - [14/Sep/2020 21:48:47] "[37mGET /set_filter/none/all/none/no/none HTTP/1.1[0m" 200 -
[2020-09-14 21:48:47,633][werkzeug][INFO] - 127.0.0.1 - - [14/Sep/2020 21:48:47] "[37mGET /get_label_value_on_image/none/0103_15_07_56_i4981_id276_cn1578064077907896000_thr540.In%20.jpg HTTP/1.1[0m" 200 -
[2020-09-14 21:48:47,636][werkzeug][INFO] - 127.0.0.1 - - [14/Sep/2020 21:48:47] "[37mGET /marked_image/0103_15_07_56_i4981_id276_cn1578064077907896000_thr540.In%20.jpg HTTP/1.1[0m" 200 -
[2020-09-14 21:48:57,560][werkzeug][INFO] - 127.0.0.1 - - [14/Sep/2020 21:48:57] "[37mGET /set_filter/none/all/person/no/none HTTP/1.1[0m" 200 -
[2020-09-14 21:48:57,588][werkzeug][INFO] - 127.0.0.1 - - [14/Sep/2020 21:48:57] "[37mGET /get_label_value_on_image/person/0103_15_07_56_i4981_id276_cn1578064077907896000_thr540.In%20.jpg HTTP/1.1[0m" 200 -
[2020-09-14 21:49:18,898][werkzeug][INFO] - 127.0.0.1 - - [14/Sep/2020 21:49:18] "[37mGET /set_filter/none/all/person/yes/none HTTP/1.1[0m" 200 -
[2020-09-14 21:49:18,902][w3classifier.app][ERROR] - Exception on /get_label_value_on_image/person/undefined [GET]
Traceback (most recent call last):
  File "/home/imt/.local/lib/python3.6/site-packages/pandas/core/indexes/base.py", line 2646, in get_loc
    return self._engine.get_loc(key)
  File "pandas/_libs/index.pyx", line 111, in pandas._libs.index.IndexEngine.get_loc
  File "pandas/_libs/index.pyx", line 138, in pandas._libs.index.IndexEngine.get_loc
  File "pandas/_libs/hashtable_class_helper.pxi", line 1619, in pandas._libs.hashtable.PyObjectHashTable.get_item
  File "pandas/_libs/hashtable_class_helper.pxi", line 1627, in pandas._libs.hashtable.PyObjectHashTable.get_item
KeyError: 'undefined'

During handling of the above exception, another exception occurred:

Traceback (most recent call last):
  File "/usr/local/lib/python3.6/dist-packages/flask/app.py", line 2447, in wsgi_app
    response = self.full_dispatch_request()
  File "/usr/local/lib/python3.6/dist-packages/flask/app.py", line 1952, in full_dispatch_request
    rv = self.handle_user_exception(e)
  File "/usr/local/lib/python3.6/dist-packages/flask_cors/extension.py", line 161, in wrapped_function
    return cors_after_request(app.make_response(f(*args, **kwargs)))
  File "/usr/local/lib/python3.6/dist-packages/flask/app.py", line 1821, in handle_user_exception
    reraise(exc_type, exc_value, tb)
  File "/usr/local/lib/python3.6/dist-packages/flask/_compat.py", line 39, in reraise
    raise value
  File "/usr/local/lib/python3.6/dist-packages/flask/app.py", line 1950, in full_dispatch_request
    rv = self.dispatch_request()
  File "/usr/local/lib/python3.6/dist-packages/flask/app.py", line 1936, in dispatch_request
    return self.view_functions[rule.endpoint](**req.view_args)
  File "/home/imt/work/pyqt5-images-classifier/w3classifier/app/views.py", line 59, in get_label_value_on_image
    return jsonify(dbs.get_label_value_on_image(label, im))
  File "/home/imt/work/pyqt5-images-classifier/w3classifier/app/module.py", line 214, in get_label_value_on_image
    return {'imlabel': self.main.at[im, label]}
  File "/home/imt/.local/lib/python3.6/site-packages/pandas/core/indexing.py", line 2179, in __getitem__
    return self.obj._get_value(*key, takeable=self._takeable)
  File "/home/imt/.local/lib/python3.6/site-packages/pandas/core/frame.py", line 2919, in _get_value
    index = self.index.get_loc(index)
  File "/home/imt/.local/lib/python3.6/site-packages/pandas/core/indexes/base.py", line 2648, in get_loc
    return self._engine.get_loc(self._maybe_cast_indexer(key))
  File "pandas/_libs/index.pyx", line 111, in pandas._libs.index.IndexEngine.get_loc
  File "pandas/_libs/index.pyx", line 138, in pandas._libs.index.IndexEngine.get_loc
  File "pandas/_libs/hashtable_class_helper.pxi", line 1619, in pandas._libs.hashtable.PyObjectHashTable.get_item
  File "pandas/_libs/hashtable_class_helper.pxi", line 1627, in pandas._libs.hashtable.PyObjectHashTable.get_item
KeyError: 'undefined'
[2020-09-14 21:49:18,903][werkzeug][INFO] - 127.0.0.1 - - [14/Sep/2020 21:49:18] "[37mGET /marked_image/undefined HTTP/1.1[0m" 200 -
[2020-09-14 21:49:18,904][werkzeug][INFO] - 127.0.0.1 - - [14/Sep/2020 21:49:18] "[35m[1mGET /get_label_value_on_image/person/undefined HTTP/1.1[0m" 500 -
[2020-09-14 21:50:25,498][werkzeug][INFO] - 127.0.0.1 - - [14/Sep/2020 21:50:25] "[37mGET /marked_image/undefined HTTP/1.1[0m" 200 -
[2020-09-14 21:50:25,526][werkzeug][INFO] - 127.0.0.1 - - [14/Sep/2020 21:50:25] "[37mGET /set_filter/none/all/none/no/none HTTP/1.1[0m" 200 -
[2020-09-14 21:50:25,566][werkzeug][INFO] - 127.0.0.1 - - [14/Sep/2020 21:50:25] "[37mGET /get_label_value_on_image/none/0103_15_07_56_i4981_id276_cn1578064077907896000_thr540.In%20.jpg HTTP/1.1[0m" 200 -
[2020-09-14 21:50:25,569][werkzeug][INFO] - 127.0.0.1 - - [14/Sep/2020 21:50:25] "[37mGET /marked_image/0103_15_07_56_i4981_id276_cn1578064077907896000_thr540.In%20.jpg HTTP/1.1[0m" 200 -
[2020-09-14 21:50:30,748][werkzeug][INFO] - 127.0.0.1 - - [14/Sep/2020 21:50:30] "[37mGET /set_filter/none/all/person/no/none HTTP/1.1[0m" 200 -
[2020-09-14 21:50:30,776][werkzeug][INFO] - 127.0.0.1 - - [14/Sep/2020 21:50:30] "[37mGET /get_label_value_on_image/person/0103_15_07_56_i4981_id276_cn1578064077907896000_thr540.In%20.jpg HTTP/1.1[0m" 200 -
[2020-09-14 21:50:57,109][werkzeug][INFO] - 127.0.0.1 - - [14/Sep/2020 21:50:57] "[37mGET /marked_image/undefined HTTP/1.1[0m" 200 -
[2020-09-14 21:50:57,126][werkzeug][INFO] - 127.0.0.1 - - [14/Sep/2020 21:50:57] "[37mGET /set_filter/none/all/none/no/none HTTP/1.1[0m" 200 -
[2020-09-14 21:50:57,158][werkzeug][INFO] - 127.0.0.1 - - [14/Sep/2020 21:50:57] "[37mGET /get_label_value_on_image/none/0103_15_07_56_i4981_id276_cn1578064077907896000_thr540.In%20.jpg HTTP/1.1[0m" 200 -
[2020-09-14 21:50:57,161][werkzeug][INFO] - 127.0.0.1 - - [14/Sep/2020 21:50:57] "[37mGET /marked_image/0103_15_07_56_i4981_id276_cn1578064077907896000_thr540.In%20.jpg HTTP/1.1[0m" 200 -
[2020-09-14 21:51:09,798][werkzeug][INFO] - 127.0.0.1 - - [14/Sep/2020 21:51:09] "[37mGET /set_filter/none/all/person/no/none HTTP/1.1[0m" 200 -
[2020-09-14 21:51:09,828][werkzeug][INFO] - 127.0.0.1 - - [14/Sep/2020 21:51:09] "[37mGET /get_label_value_on_image/person/0103_15_07_56_i4981_id276_cn1578064077907896000_thr540.In%20.jpg HTTP/1.1[0m" 200 -
[2020-09-14 21:56:40,732][werkzeug][INFO] - 127.0.0.1 - - [14/Sep/2020 21:56:40] "[37mGET /set_filter/none/all/l_carring/no/none HTTP/1.1[0m" 200 -
[2020-09-14 21:56:40,764][werkzeug][INFO] - 127.0.0.1 - - [14/Sep/2020 21:56:40] "[37mGET /get_label_value_on_image/l_carring/0103_15_07_56_i4981_id276_cn1578064077907896000_thr540.In%20.jpg HTTP/1.1[0m" 200 -
[2020-09-14 21:56:45,365][werkzeug][INFO] - 127.0.0.1 - - [14/Sep/2020 21:56:45] "[37mGET /set_filter/l_carring/all/l_carring/no/none HTTP/1.1[0m" 200 -
[2020-09-14 21:56:45,370][werkzeug][INFO] - 127.0.0.1 - - [14/Sep/2020 21:56:45] "[37mGET /get_label_value_on_image/l_carring/0103_15_07_56_i4981_id276_cn1578064077907896000_thr540.In%20.jpg HTTP/1.1[0m" 200 -
[2020-09-14 21:56:46,888][werkzeug][INFO] - 127.0.0.1 - - [14/Sep/2020 21:56:46] "[37mGET /set_filter/l_carring/non_visible/l_carring/no/none HTTP/1.1[0m" 200 -
[2020-09-14 21:56:46,892][werkzeug][INFO] - 127.0.0.1 - - [14/Sep/2020 21:56:46] "[37mGET /get_label_value_on_image/l_carring/0104_10_29_45_i697483_id10352_cn1578133840571341000_thr839.Sg_bord%20looks_different.jpg HTTP/1.1[0m" 200 -
[2020-09-14 21:56:46,899][werkzeug][INFO] - 127.0.0.1 - - [14/Sep/2020 21:56:46] "[37mGET /marked_image/0104_10_29_45_i697483_id10352_cn1578133840571341000_thr839.Sg_bord%20looks_different.jpg HTTP/1.1[0m" 200 -
[2020-09-14 21:56:50,889][werkzeug][INFO] - 127.0.0.1 - - [14/Sep/2020 21:56:50] "[37mGET /set_filter/l_carring/non_visible/face_visible/no/none HTTP/1.1[0m" 200 -
[2020-09-14 21:56:50,893][werkzeug][INFO] - 127.0.0.1 - - [14/Sep/2020 21:56:50] "[37mGET /get_label_value_on_image/face_visible/0104_10_29_45_i697483_id10352_cn1578133840571341000_thr839.Sg_bord%20looks_different.jpg HTTP/1.1[0m" 200 -
[2020-09-14 21:56:54,392][werkzeug][INFO] - 127.0.0.1 - - [14/Sep/2020 21:56:54] "[37mGET /set_filter/l_carring/non_visible/face_visible/yes/none HTTP/1.1[0m" 200 -
[2020-09-14 21:56:54,396][w3classifier.app][ERROR] - Exception on /get_label_value_on_image/face_visible/undefined [GET]
Traceback (most recent call last):
  File "/home/imt/.local/lib/python3.6/site-packages/pandas/core/indexes/base.py", line 2646, in get_loc
    return self._engine.get_loc(key)
  File "pandas/_libs/index.pyx", line 111, in pandas._libs.index.IndexEngine.get_loc
  File "pandas/_libs/index.pyx", line 138, in pandas._libs.index.IndexEngine.get_loc
  File "pandas/_libs/hashtable_class_helper.pxi", line 1619, in pandas._libs.hashtable.PyObjectHashTable.get_item
  File "pandas/_libs/hashtable_class_helper.pxi", line 1627, in pandas._libs.hashtable.PyObjectHashTable.get_item
KeyError: 'undefined'

During handling of the above exception, another exception occurred:

Traceback (most recent call last):
  File "/usr/local/lib/python3.6/dist-packages/flask/app.py", line 2447, in wsgi_app
    response = self.full_dispatch_request()
  File "/usr/local/lib/python3.6/dist-packages/flask/app.py", line 1952, in full_dispatch_request
    rv = self.handle_user_exception(e)
  File "/usr/local/lib/python3.6/dist-packages/flask_cors/extension.py", line 161, in wrapped_function
    return cors_after_request(app.make_response(f(*args, **kwargs)))
  File "/usr/local/lib/python3.6/dist-packages/flask/app.py", line 1821, in handle_user_exception
    reraise(exc_type, exc_value, tb)
  File "/usr/local/lib/python3.6/dist-packages/flask/_compat.py", line 39, in reraise
    raise value
  File "/usr/local/lib/python3.6/dist-packages/flask/app.py", line 1950, in full_dispatch_request
    rv = self.dispatch_request()
  File "/usr/local/lib/python3.6/dist-packages/flask/app.py", line 1936, in dispatch_request
    return self.view_functions[rule.endpoint](**req.view_args)
  File "/home/imt/work/pyqt5-images-classifier/w3classifier/app/views.py", line 59, in get_label_value_on_image
    return jsonify(dbs.get_label_value_on_image(label, im))
  File "/home/imt/work/pyqt5-images-classifier/w3classifier/app/module.py", line 214, in get_label_value_on_image
    return {'imlabel': self.main.at[im, label]}
  File "/home/imt/.local/lib/python3.6/site-packages/pandas/core/indexing.py", line 2179, in __getitem__
    return self.obj._get_value(*key, takeable=self._takeable)
  File "/home/imt/.local/lib/python3.6/site-packages/pandas/core/frame.py", line 2919, in _get_value
    index = self.index.get_loc(index)
  File "/home/imt/.local/lib/python3.6/site-packages/pandas/core/indexes/base.py", line 2648, in get_loc
    return self._engine.get_loc(self._maybe_cast_indexer(key))
  File "pandas/_libs/index.pyx", line 111, in pandas._libs.index.IndexEngine.get_loc
  File "pandas/_libs/index.pyx", line 138, in pandas._libs.index.IndexEngine.get_loc
  File "pandas/_libs/hashtable_class_helper.pxi", line 1619, in pandas._libs.hashtable.PyObjectHashTable.get_item
  File "pandas/_libs/hashtable_class_helper.pxi", line 1627, in pandas._libs.hashtable.PyObjectHashTable.get_item
KeyError: 'undefined'
[2020-09-14 21:56:54,397][werkzeug][INFO] - 127.0.0.1 - - [14/Sep/2020 21:56:54] "[37mGET /marked_image/undefined HTTP/1.1[0m" 200 -
[2020-09-14 21:56:54,398][werkzeug][INFO] - 127.0.0.1 - - [14/Sep/2020 21:56:54] "[35m[1mGET /get_label_value_on_image/face_visible/undefined HTTP/1.1[0m" 500 -
[2020-09-14 21:57:11,907][werkzeug][INFO] - 127.0.0.1 - - [14/Sep/2020 21:57:11] "[37mGET /marked_image/undefined HTTP/1.1[0m" 200 -
[2020-09-14 21:57:11,959][werkzeug][INFO] - 127.0.0.1 - - [14/Sep/2020 21:57:11] "[33mGET /favicon.ico HTTP/1.1[0m" 404 -
[2020-09-14 21:57:55,071][werkzeug][INFO] - 127.0.0.1 - - [14/Sep/2020 21:57:55] "[37mGET /set_filter/l_carring/non_visible/face_visible/no/none HTTP/1.1[0m" 200 -
[2020-09-14 21:57:55,076][werkzeug][INFO] - 127.0.0.1 - - [14/Sep/2020 21:57:55] "[37mGET /get_label_value_on_image/face_visible/0104_10_29_45_i697483_id10352_cn1578133840571341000_thr839.Sg_bord%20looks_different.jpg HTTP/1.1[0m" 200 -
[2020-09-14 21:58:03,352][werkzeug][INFO] - 127.0.0.1 - - [14/Sep/2020 21:58:03] "[37mGET /set_filter/person/non_visible/face_visible/no/none HTTP/1.1[0m" 200 -
[2020-09-14 21:58:03,357][w3classifier.app][ERROR] - Exception on /get_label_value_on_image/face_visible/undefined [GET]
Traceback (most recent call last):
  File "/home/imt/.local/lib/python3.6/site-packages/pandas/core/indexes/base.py", line 2646, in get_loc
    return self._engine.get_loc(key)
  File "pandas/_libs/index.pyx", line 111, in pandas._libs.index.IndexEngine.get_loc
  File "pandas/_libs/index.pyx", line 138, in pandas._libs.index.IndexEngine.get_loc
  File "pandas/_libs/hashtable_class_helper.pxi", line 1619, in pandas._libs.hashtable.PyObjectHashTable.get_item
  File "pandas/_libs/hashtable_class_helper.pxi", line 1627, in pandas._libs.hashtable.PyObjectHashTable.get_item
KeyError: 'undefined'

During handling of the above exception, another exception occurred:

Traceback (most recent call last):
  File "/usr/local/lib/python3.6/dist-packages/flask/app.py", line 2447, in wsgi_app
    response = self.full_dispatch_request()
  File "/usr/local/lib/python3.6/dist-packages/flask/app.py", line 1952, in full_dispatch_request
    rv = self.handle_user_exception(e)
  File "/usr/local/lib/python3.6/dist-packages/flask_cors/extension.py", line 161, in wrapped_function
    return cors_after_request(app.make_response(f(*args, **kwargs)))
  File "/usr/local/lib/python3.6/dist-packages/flask/app.py", line 1821, in handle_user_exception
    reraise(exc_type, exc_value, tb)
  File "/usr/local/lib/python3.6/dist-packages/flask/_compat.py", line 39, in reraise
    raise value
  File "/usr/local/lib/python3.6/dist-packages/flask/app.py", line 1950, in full_dispatch_request
    rv = self.dispatch_request()
  File "/usr/local/lib/python3.6/dist-packages/flask/app.py", line 1936, in dispatch_request
    return self.view_functions[rule.endpoint](**req.view_args)
  File "/home/imt/work/pyqt5-images-classifier/w3classifier/app/views.py", line 59, in get_label_value_on_image
    return jsonify(dbs.get_label_value_on_image(label, im))
  File "/home/imt/work/pyqt5-images-classifier/w3classifier/app/module.py", line 214, in get_label_value_on_image
    return {'imlabel': self.main.at[im, label]}
  File "/home/imt/.local/lib/python3.6/site-packages/pandas/core/indexing.py", line 2179, in __getitem__
    return self.obj._get_value(*key, takeable=self._takeable)
  File "/home/imt/.local/lib/python3.6/site-packages/pandas/core/frame.py", line 2919, in _get_value
    index = self.index.get_loc(index)
  File "/home/imt/.local/lib/python3.6/site-packages/pandas/core/indexes/base.py", line 2648, in get_loc
    return self._engine.get_loc(self._maybe_cast_indexer(key))
  File "pandas/_libs/index.pyx", line 111, in pandas._libs.index.IndexEngine.get_loc
  File "pandas/_libs/index.pyx", line 138, in pandas._libs.index.IndexEngine.get_loc
  File "pandas/_libs/hashtable_class_helper.pxi", line 1619, in pandas._libs.hashtable.PyObjectHashTable.get_item
  File "pandas/_libs/hashtable_class_helper.pxi", line 1627, in pandas._libs.hashtable.PyObjectHashTable.get_item
KeyError: 'undefined'
[2020-09-14 21:58:03,358][werkzeug][INFO] - 127.0.0.1 - - [14/Sep/2020 21:58:03] "[37mGET /marked_image/undefined HTTP/1.1[0m" 200 -
[2020-09-14 21:58:03,359][werkzeug][INFO] - 127.0.0.1 - - [14/Sep/2020 21:58:03] "[35m[1mGET /get_label_value_on_image/face_visible/undefined HTTP/1.1[0m" 500 -
[2020-09-14 21:58:05,138][werkzeug][INFO] - 127.0.0.1 - - [14/Sep/2020 21:58:05] "[37mGET /set_filter/none/non_visible/face_visible/no/none HTTP/1.1[0m" 200 -
[2020-09-14 21:58:05,165][werkzeug][INFO] - 127.0.0.1 - - [14/Sep/2020 21:58:05] "[37mGET /get_label_value_on_image/face_visible/0103_15_07_56_i4981_id276_cn1578064077907896000_thr540.In%20.jpg HTTP/1.1[0m" 200 -
[2020-09-14 21:58:06,752][werkzeug][INFO] - 127.0.0.1 - - [14/Sep/2020 21:58:06] "[37mGET /set_filter/none/non_visible/face_visible/no/up HTTP/1.1[0m" 200 -
[2020-09-14 21:58:06,778][werkzeug][INFO] - 127.0.0.1 - - [14/Sep/2020 21:58:06] "[37mGET /get_label_value_on_image/face_visible/0103_15_07_56_i4981_id276_cn1578064077907896000_thr540.In%20.jpg HTTP/1.1[0m" 200 -
[2020-09-14 21:58:11,365][werkzeug][INFO] - 127.0.0.1 - - [14/Sep/2020 21:58:11] "[37mGET /set_filter/none/non_visible/person/no/up HTTP/1.1[0m" 200 -
[2020-09-14 21:58:11,392][werkzeug][INFO] - 127.0.0.1 - - [14/Sep/2020 21:58:11] "[37mGET /get_label_value_on_image/person/0103_15_07_56_i4981_id276_cn1578064077907896000_thr540.In%20.jpg HTTP/1.1[0m" 200 -
[2020-09-14 21:58:18,893][werkzeug][INFO] - 127.0.0.1 - - [14/Sep/2020 21:58:18] "[37mGET /set_filter/none/non_visible/person/yes/up HTTP/1.1[0m" 200 -
[2020-09-14 21:58:18,896][w3classifier.app][ERROR] - Exception on /get_label_value_on_image/person/undefined [GET]
Traceback (most recent call last):
  File "/home/imt/.local/lib/python3.6/site-packages/pandas/core/indexes/base.py", line 2646, in get_loc
    return self._engine.get_loc(key)
  File "pandas/_libs/index.pyx", line 111, in pandas._libs.index.IndexEngine.get_loc
  File "pandas/_libs/index.pyx", line 138, in pandas._libs.index.IndexEngine.get_loc
  File "pandas/_libs/hashtable_class_helper.pxi", line 1619, in pandas._libs.hashtable.PyObjectHashTable.get_item
  File "pandas/_libs/hashtable_class_helper.pxi", line 1627, in pandas._libs.hashtable.PyObjectHashTable.get_item
KeyError: 'undefined'

During handling of the above exception, another exception occurred:

Traceback (most recent call last):
  File "/usr/local/lib/python3.6/dist-packages/flask/app.py", line 2447, in wsgi_app
    response = self.full_dispatch_request()
  File "/usr/local/lib/python3.6/dist-packages/flask/app.py", line 1952, in full_dispatch_request
    rv = self.handle_user_exception(e)
  File "/usr/local/lib/python3.6/dist-packages/flask_cors/extension.py", line 161, in wrapped_function
    return cors_after_request(app.make_response(f(*args, **kwargs)))
  File "/usr/local/lib/python3.6/dist-packages/flask/app.py", line 1821, in handle_user_exception
    reraise(exc_type, exc_value, tb)
  File "/usr/local/lib/python3.6/dist-packages/flask/_compat.py", line 39, in reraise
    raise value
  File "/usr/local/lib/python3.6/dist-packages/flask/app.py", line 1950, in full_dispatch_request
    rv = self.dispatch_request()
  File "/usr/local/lib/python3.6/dist-packages/flask/app.py", line 1936, in dispatch_request
    return self.view_functions[rule.endpoint](**req.view_args)
  File "/home/imt/work/pyqt5-images-classifier/w3classifier/app/views.py", line 59, in get_label_value_on_image
    return jsonify(dbs.get_label_value_on_image(label, im))
  File "/home/imt/work/pyqt5-images-classifier/w3classifier/app/module.py", line 214, in get_label_value_on_image
    return {'imlabel': self.main.at[im, label]}
  File "/home/imt/.local/lib/python3.6/site-packages/pandas/core/indexing.py", line 2179, in __getitem__
    return self.obj._get_value(*key, takeable=self._takeable)
  File "/home/imt/.local/lib/python3.6/site-packages/pandas/core/frame.py", line 2919, in _get_value
    index = self.index.get_loc(index)
  File "/home/imt/.local/lib/python3.6/site-packages/pandas/core/indexes/base.py", line 2648, in get_loc
    return self._engine.get_loc(self._maybe_cast_indexer(key))
  File "pandas/_libs/index.pyx", line 111, in pandas._libs.index.IndexEngine.get_loc
  File "pandas/_libs/index.pyx", line 138, in pandas._libs.index.IndexEngine.get_loc
  File "pandas/_libs/hashtable_class_helper.pxi", line 1619, in pandas._libs.hashtable.PyObjectHashTable.get_item
  File "pandas/_libs/hashtable_class_helper.pxi", line 1627, in pandas._libs.hashtable.PyObjectHashTable.get_item
KeyError: 'undefined'
[2020-09-14 21:58:18,896][werkzeug][INFO] - 127.0.0.1 - - [14/Sep/2020 21:58:18] "[35m[1mGET /get_label_value_on_image/person/undefined HTTP/1.1[0m" 500 -
[2020-09-14 21:58:18,897][werkzeug][INFO] - 127.0.0.1 - - [14/Sep/2020 21:58:18] "[37mGET /marked_image/undefined HTTP/1.1[0m" 200 -
[2020-09-14 21:58:21,754][werkzeug][INFO] - 127.0.0.1 - - [14/Sep/2020 21:58:21] "[37mGET /set_filter/none/non_visible/person/no/up HTTP/1.1[0m" 200 -
[2020-09-14 21:58:21,782][werkzeug][INFO] - 127.0.0.1 - - [14/Sep/2020 21:58:21] "[37mGET /get_label_value_on_image/person/0103_15_07_56_i4981_id276_cn1578064077907896000_thr540.In%20.jpg HTTP/1.1[0m" 200 -
[2020-09-14 21:58:21,785][werkzeug][INFO] - 127.0.0.1 - - [14/Sep/2020 21:58:21] "[37mGET /marked_image/0103_15_07_56_i4981_id276_cn1578064077907896000_thr540.In%20.jpg HTTP/1.1[0m" 200 -
[2020-09-14 21:58:24,517][werkzeug][INFO] - 127.0.0.1 - - [14/Sep/2020 21:58:24] "[37mGET /get_label_value_on_image/person/0315_10_33_42___i7_SNGL_CLR_TP1_ID27_CAM0_TP1_THR750_CN1584268423251465000_TCN-27_MOTION.png HTTP/1.1[0m" 200 -
[2020-09-14 21:58:24,526][werkzeug][INFO] - 127.0.0.1 - - [14/Sep/2020 21:58:24] "[37mGET /marked_image/0315_10_33_42___i7_SNGL_CLR_TP1_ID27_CAM0_TP1_THR750_CN1584268423251465000_TCN-27_MOTION.png HTTP/1.1[0m" 200 -
[2020-09-14 21:58:25,284][werkzeug][INFO] - 127.0.0.1 - - [14/Sep/2020 21:58:25] "[37mGET /get_label_value_on_image/person/2019-08-30_10-29-38_id68263_leaves__camp_area.jpg HTTP/1.1[0m" 200 -
[2020-09-14 21:58:25,288][werkzeug][INFO] - 127.0.0.1 - - [14/Sep/2020 21:58:25] "[37mGET /marked_image/2019-08-30_10-29-38_id68263_leaves__camp_area.jpg HTTP/1.1[0m" 200 -
[2020-09-14 21:58:26,029][werkzeug][INFO] - 127.0.0.1 - - [14/Sep/2020 21:58:26] "[37mGET /get_label_value_on_image/person/2019-11-28_11-46-08_i=15108_id=5700_cn=1574941562258796000_thr=588_descr_Out_looks_different.jpg HTTP/1.1[0m" 200 -
[2020-09-14 21:58:26,031][werkzeug][INFO] - 127.0.0.1 - - [14/Sep/2020 21:58:26] "[37mGET /marked_image/2019-11-28_11-46-08_i=15108_id=5700_cn=1574941562258796000_thr=588_descr_Out_looks_different.jpg HTTP/1.1[0m" 200 -
[2020-09-14 21:58:26,484][werkzeug][INFO] - 127.0.0.1 - - [14/Sep/2020 21:58:26] "[37mGET /get_label_value_on_image/person/0415_16_28_15___i30104958_LOOK_CLR_TP1_ID17726510_CAM0_TP1_THR797_CN1586968137080927000_TCN-17726510.png HTTP/1.1[0m" 200 -
[2020-09-14 21:58:26,490][werkzeug][INFO] - 127.0.0.1 - - [14/Sep/2020 21:58:26] "[37mGET /marked_image/0415_16_28_15___i30104958_LOOK_CLR_TP1_ID17726510_CAM0_TP1_THR797_CN1586968137080927000_TCN-17726510.png HTTP/1.1[0m" 200 -
[2020-09-14 21:58:27,757][werkzeug][INFO] - 127.0.0.1 - - [14/Sep/2020 21:58:27] "[37mGET /get_label_value_on_image/person/0418_09_01_12___i723360_IN________________CR_TP1_ID382622_CAM0_TP1_THR750_CN1587200494892856000_TCN-382622_MN.png HTTP/1.1[0m" 200 -
[2020-09-14 21:58:27,765][werkzeug][INFO] - 127.0.0.1 - - [14/Sep/2020 21:58:27] "[37mGET /marked_image/0418_09_01_12___i723360_IN________________CR_TP1_ID382622_CAM0_TP1_THR750_CN1587200494892856000_TCN-382622_MN.png HTTP/1.1[0m" 200 -
[2020-09-14 21:58:28,589][werkzeug][INFO] - 127.0.0.1 - - [14/Sep/2020 21:58:28] "[37mGET /get_label_value_on_image/person/0424_13_58_15___i544465__________SM__________TP1_ID402966_CAM0_TP1_THR750_CN1587736708748690000_TCN-402966_MN.png HTTP/1.1[0m" 200 -
[2020-09-14 21:58:28,592][werkzeug][INFO] - 127.0.0.1 - - [14/Sep/2020 21:58:28] "[37mGET /marked_image/0424_13_58_15___i544465__________SM__________TP1_ID402966_CAM0_TP1_THR750_CN1587736708748690000_TCN-402966_MN.png HTTP/1.1[0m" 200 -
[2020-09-14 21:58:29,302][werkzeug][INFO] - 127.0.0.1 - - [14/Sep/2020 21:58:29] "[37mGET /get_label_value_on_image/person/0424_10_41_48___i2384956__________SM_______CR_TP1_ID503097_CAM0_TP1_THR920_CN1587724905064316000_TCN-503097___.png HTTP/1.1[0m" 200 -
[2020-09-14 21:58:29,318][werkzeug][INFO] - 127.0.0.1 - - [14/Sep/2020 21:58:29] "[37mGET /marked_image/0424_10_41_48___i2384956__________SM_______CR_TP1_ID503097_CAM0_TP1_THR920_CN1587724905064316000_TCN-503097___.png HTTP/1.1[0m" 200 -
[2020-09-14 21:58:30,061][werkzeug][INFO] - 127.0.0.1 - - [14/Sep/2020 21:58:30] "[37mGET /get_label_value_on_image/person/0504_16_27_47___i2930751__________SM_______CR_TP1_ID876844_CAM0_TP1_THR692_CN1588609684235102000_TCN-876844___.png HTTP/1.1[0m" 200 -
[2020-09-14 21:58:30,064][werkzeug][INFO] - 127.0.0.1 - - [14/Sep/2020 21:58:30] "[37mGET /marked_image/0504_16_27_47___i2930751__________SM_______CR_TP1_ID876844_CAM0_TP1_THR692_CN1588609684235102000_TCN-876844___.png HTTP/1.1[0m" 200 -
[2020-09-14 21:58:30,805][werkzeug][INFO] - 127.0.0.1 - - [14/Sep/2020 21:58:30] "[37mGET /get_label_value_on_image/person/0512_11_21_27___i12518440_IN________________CR_TP1_ID4538631_CAM0_TP1_THR982_CN1589282497016265000_TCN-4538631___.png HTTP/1.1[0m" 200 -
[2020-09-14 21:58:30,810][werkzeug][INFO] - 127.0.0.1 - - [14/Sep/2020 21:58:30] "[37mGET /marked_image/0512_11_21_27___i12518440_IN________________CR_TP1_ID4538631_CAM0_TP1_THR982_CN1589282497016265000_TCN-4538631___.png HTTP/1.1[0m" 200 -
[2020-09-14 21:58:31,413][werkzeug][INFO] - 127.0.0.1 - - [14/Sep/2020 21:58:31] "[37mGET /get_label_value_on_image/person/2020-05-01-12:26:18.png HTTP/1.1[0m" 200 -
[2020-09-14 21:58:31,494][werkzeug][INFO] - 127.0.0.1 - - [14/Sep/2020 21:58:31] "[37mGET /marked_image/2020-05-01-12:26:18.png HTTP/1.1[0m" 200 -
[2020-09-14 21:58:32,749][werkzeug][INFO] - 127.0.0.1 - - [14/Sep/2020 21:58:32] "[37mGET /get_label_value_on_image/person/0528_09_23_40___i13508__________SM__________TP1_ID9827_CAM0_TP1_THR919_CN1590657823217808000_TCN-9827___.png HTTP/1.1[0m" 200 -
[2020-09-14 21:58:32,755][werkzeug][INFO] - 127.0.0.1 - - [14/Sep/2020 21:58:32] "[37mGET /marked_image/0528_09_23_40___i13508__________SM__________TP1_ID9827_CAM0_TP1_THR919_CN1590657823217808000_TCN-9827___.png HTTP/1.1[0m" 200 -
[2020-09-14 21:58:33,623][werkzeug][INFO] - 127.0.0.1 - - [14/Sep/2020 21:58:33] "[37mGET /get_label_value_on_image/person/0028514__0709__13_53_28_______END.png HTTP/1.1[0m" 200 -
[2020-09-14 21:58:33,628][werkzeug][INFO] - 127.0.0.1 - - [14/Sep/2020 21:58:33] "[37mGET /marked_image/0028514__0709__13_53_28_______END.png HTTP/1.1[0m" 200 -
[2020-09-14 21:58:34,344][werkzeug][INFO] - 127.0.0.1 - - [14/Sep/2020 21:58:34] "[37mGET /get_label_value_on_image/person/0724730__0708__09_56_38_______END.png HTTP/1.1[0m" 200 -
[2020-09-14 21:58:34,347][werkzeug][INFO] - 127.0.0.1 - - [14/Sep/2020 21:58:34] "[37mGET /marked_image/0724730__0708__09_56_38_______END.png HTTP/1.1[0m" 200 -
[2020-09-14 21:58:34,893][werkzeug][INFO] - 127.0.0.1 - - [14/Sep/2020 21:58:34] "[37mGET /get_label_value_on_image/person/0702105__0705__12_51_07_PC_______.png HTTP/1.1[0m" 200 -
[2020-09-14 21:58:34,897][werkzeug][INFO] - 127.0.0.1 - - [14/Sep/2020 21:58:34] "[37mGET /marked_image/0702105__0705__12_51_07_PC_______.png HTTP/1.1[0m" 200 -
[2020-09-14 21:58:35,110][werkzeug][INFO] - 127.0.0.1 - - [14/Sep/2020 21:58:35] "[37mGET /get_label_value_on_image/person/0580152__0717__11_31_31_______END.png HTTP/1.1[0m" 200 -
[2020-09-14 21:58:35,114][werkzeug][INFO] - 127.0.0.1 - - [14/Sep/2020 21:58:35] "[37mGET /marked_image/0580152__0717__11_31_31_______END.png HTTP/1.1[0m" 200 -
[2020-09-14 21:58:35,326][werkzeug][INFO] - 127.0.0.1 - - [14/Sep/2020 21:58:35] "[37mGET /get_label_value_on_image/person/0750831__0717__16_15_56_______END.png HTTP/1.1[0m" 200 -
[2020-09-14 21:58:35,348][werkzeug][INFO] - 127.0.0.1 - - [14/Sep/2020 21:58:35] "[37mGET /marked_image/0750831__0717__16_15_56_______END.png HTTP/1.1[0m" 200 -
[2020-09-14 21:58:35,559][werkzeug][INFO] - 127.0.0.1 - - [14/Sep/2020 21:58:35] "[37mGET /get_label_value_on_image/person/1297471__0718__07_26_52_PC_______.png HTTP/1.1[0m" 200 -
[2020-09-14 21:58:35,562][werkzeug][INFO] - 127.0.0.1 - - [14/Sep/2020 21:58:35] "[37mGET /marked_image/1297471__0718__07_26_52_PC_______.png HTTP/1.1[0m" 200 -
[2020-09-14 21:59:37,186][werkzeug][INFO] - 127.0.0.1 - - [14/Sep/2020 21:59:37] "[37mGET /marked_image/undefined HTTP/1.1[0m" 200 -
[2020-09-14 21:59:37,201][werkzeug][INFO] - 127.0.0.1 - - [14/Sep/2020 21:59:37] "[37mGET /set_filter/none/all/none/no/none HTTP/1.1[0m" 200 -
[2020-09-14 21:59:37,239][werkzeug][INFO] - 127.0.0.1 - - [14/Sep/2020 21:59:37] "[37mGET /get_label_value_on_image/none/0103_15_07_56_i4981_id276_cn1578064077907896000_thr540.In%20.jpg HTTP/1.1[0m" 200 -
[2020-09-14 21:59:37,242][werkzeug][INFO] - 127.0.0.1 - - [14/Sep/2020 21:59:37] "[37mGET /marked_image/0103_15_07_56_i4981_id276_cn1578064077907896000_thr540.In%20.jpg HTTP/1.1[0m" 200 -
[2020-09-14 21:59:40,150][werkzeug][INFO] - 127.0.0.1 - - [14/Sep/2020 21:59:40] "[37mGET /set_filter/none/all/person/no/none HTTP/1.1[0m" 200 -
[2020-09-14 21:59:40,182][werkzeug][INFO] - 127.0.0.1 - - [14/Sep/2020 21:59:40] "[37mGET /get_label_value_on_image/person/0103_15_07_56_i4981_id276_cn1578064077907896000_thr540.In%20.jpg HTTP/1.1[0m" 200 -
[2020-09-14 21:59:42,268][werkzeug][INFO] - 127.0.0.1 - - [14/Sep/2020 21:59:42] "[37mGET /set_filter/none/all/person/yes/none HTTP/1.1[0m" 200 -
[2020-09-14 21:59:42,271][w3classifier.app][ERROR] - Exception on /get_label_value_on_image/person/undefined [GET]
Traceback (most recent call last):
  File "/home/imt/.local/lib/python3.6/site-packages/pandas/core/indexes/base.py", line 2646, in get_loc
    return self._engine.get_loc(key)
  File "pandas/_libs/index.pyx", line 111, in pandas._libs.index.IndexEngine.get_loc
  File "pandas/_libs/index.pyx", line 138, in pandas._libs.index.IndexEngine.get_loc
  File "pandas/_libs/hashtable_class_helper.pxi", line 1619, in pandas._libs.hashtable.PyObjectHashTable.get_item
  File "pandas/_libs/hashtable_class_helper.pxi", line 1627, in pandas._libs.hashtable.PyObjectHashTable.get_item
KeyError: 'undefined'

During handling of the above exception, another exception occurred:

Traceback (most recent call last):
  File "/usr/local/lib/python3.6/dist-packages/flask/app.py", line 2447, in wsgi_app
    response = self.full_dispatch_request()
  File "/usr/local/lib/python3.6/dist-packages/flask/app.py", line 1952, in full_dispatch_request
    rv = self.handle_user_exception(e)
  File "/usr/local/lib/python3.6/dist-packages/flask_cors/extension.py", line 161, in wrapped_function
    return cors_after_request(app.make_response(f(*args, **kwargs)))
  File "/usr/local/lib/python3.6/dist-packages/flask/app.py", line 1821, in handle_user_exception
    reraise(exc_type, exc_value, tb)
  File "/usr/local/lib/python3.6/dist-packages/flask/_compat.py", line 39, in reraise
    raise value
  File "/usr/local/lib/python3.6/dist-packages/flask/app.py", line 1950, in full_dispatch_request
    rv = self.dispatch_request()
  File "/usr/local/lib/python3.6/dist-packages/flask/app.py", line 1936, in dispatch_request
    return self.view_functions[rule.endpoint](**req.view_args)
  File "/home/imt/work/pyqt5-images-classifier/w3classifier/app/views.py", line 59, in get_label_value_on_image
    return jsonify(dbs.get_label_value_on_image(label, im))
  File "/home/imt/work/pyqt5-images-classifier/w3classifier/app/module.py", line 214, in get_label_value_on_image
    return {'imlabel': self.main.at[im, label]}
  File "/home/imt/.local/lib/python3.6/site-packages/pandas/core/indexing.py", line 2179, in __getitem__
    return self.obj._get_value(*key, takeable=self._takeable)
  File "/home/imt/.local/lib/python3.6/site-packages/pandas/core/frame.py", line 2919, in _get_value
    index = self.index.get_loc(index)
  File "/home/imt/.local/lib/python3.6/site-packages/pandas/core/indexes/base.py", line 2648, in get_loc
    return self._engine.get_loc(self._maybe_cast_indexer(key))
  File "pandas/_libs/index.pyx", line 111, in pandas._libs.index.IndexEngine.get_loc
  File "pandas/_libs/index.pyx", line 138, in pandas._libs.index.IndexEngine.get_loc
  File "pandas/_libs/hashtable_class_helper.pxi", line 1619, in pandas._libs.hashtable.PyObjectHashTable.get_item
  File "pandas/_libs/hashtable_class_helper.pxi", line 1627, in pandas._libs.hashtable.PyObjectHashTable.get_item
KeyError: 'undefined'
[2020-09-14 21:59:42,272][werkzeug][INFO] - 127.0.0.1 - - [14/Sep/2020 21:59:42] "[37mGET /marked_image/undefined HTTP/1.1[0m" 200 -
[2020-09-14 21:59:42,273][werkzeug][INFO] - 127.0.0.1 - - [14/Sep/2020 21:59:42] "[35m[1mGET /get_label_value_on_image/person/undefined HTTP/1.1[0m" 500 -
[2020-09-14 22:03:10,397][werkzeug][INFO] - 127.0.0.1 - - [14/Sep/2020 22:03:10] "[37mGET /marked_image/undefined HTTP/1.1[0m" 200 -
[2020-09-14 22:03:10,414][werkzeug][INFO] - 127.0.0.1 - - [14/Sep/2020 22:03:10] "[37mGET /set_filter/none/all/none/no/none HTTP/1.1[0m" 200 -
[2020-09-14 22:03:10,447][werkzeug][INFO] - 127.0.0.1 - - [14/Sep/2020 22:03:10] "[37mGET /get_label_value_on_image/none/0103_15_07_56_i4981_id276_cn1578064077907896000_thr540.In%20.jpg HTTP/1.1[0m" 200 -
[2020-09-14 22:03:10,451][werkzeug][INFO] - 127.0.0.1 - - [14/Sep/2020 22:03:10] "[37mGET /marked_image/0103_15_07_56_i4981_id276_cn1578064077907896000_thr540.In%20.jpg HTTP/1.1[0m" 200 -
[2020-09-14 22:03:15,270][werkzeug][INFO] - 127.0.0.1 - - [14/Sep/2020 22:03:15] "[37mGET /marked_image/undefined HTTP/1.1[0m" 200 -
[2020-09-14 22:03:15,297][werkzeug][INFO] - 127.0.0.1 - - [14/Sep/2020 22:03:15] "[37mGET /set_filter/none/all/none/no/none HTTP/1.1[0m" 200 -
[2020-09-14 22:03:15,326][werkzeug][INFO] - 127.0.0.1 - - [14/Sep/2020 22:03:15] "[37mGET /get_label_value_on_image/none/0103_15_07_56_i4981_id276_cn1578064077907896000_thr540.In%20.jpg HTTP/1.1[0m" 200 -
[2020-09-14 22:03:15,329][werkzeug][INFO] - 127.0.0.1 - - [14/Sep/2020 22:03:15] "[37mGET /marked_image/0103_15_07_56_i4981_id276_cn1578064077907896000_thr540.In%20.jpg HTTP/1.1[0m" 200 -
[2020-09-14 22:03:17,154][werkzeug][INFO] - 127.0.0.1 - - [14/Sep/2020 22:03:17] "[37mGET /set_filter/none/all/person/no/none HTTP/1.1[0m" 200 -
[2020-09-14 22:03:17,181][werkzeug][INFO] - 127.0.0.1 - - [14/Sep/2020 22:03:17] "[37mGET /get_label_value_on_image/person/0103_15_07_56_i4981_id276_cn1578064077907896000_thr540.In%20.jpg HTTP/1.1[0m" 200 -
[2020-09-14 22:03:47,473][werkzeug][INFO] - 127.0.0.1 - - [14/Sep/2020 22:03:47] "[37mGET /marked_image/undefined HTTP/1.1[0m" 200 -
[2020-09-14 22:03:47,491][werkzeug][INFO] - 127.0.0.1 - - [14/Sep/2020 22:03:47] "[37mGET /set_filter/none/all/none/no/none HTTP/1.1[0m" 200 -
[2020-09-14 22:03:47,525][werkzeug][INFO] - 127.0.0.1 - - [14/Sep/2020 22:03:47] "[37mGET /get_label_value_on_image/none/0103_15_07_56_i4981_id276_cn1578064077907896000_thr540.In%20.jpg HTTP/1.1[0m" 200 -
[2020-09-14 22:03:47,528][werkzeug][INFO] - 127.0.0.1 - - [14/Sep/2020 22:03:47] "[37mGET /marked_image/0103_15_07_56_i4981_id276_cn1578064077907896000_thr540.In%20.jpg HTTP/1.1[0m" 200 -
[2020-09-14 22:03:54,264][werkzeug][INFO] - 127.0.0.1 - - [14/Sep/2020 22:03:54] "[37mGET /set_filter/none/all/person/no/none HTTP/1.1[0m" 200 -
[2020-09-14 22:03:54,310][werkzeug][INFO] - 127.0.0.1 - - [14/Sep/2020 22:03:54] "[37mGET /get_label_value_on_image/person/0103_15_07_56_i4981_id276_cn1578064077907896000_thr540.In%20.jpg HTTP/1.1[0m" 200 -
[2020-09-14 22:04:22,955][werkzeug][INFO] - 127.0.0.1 - - [14/Sep/2020 22:04:22] "[37mGET /marked_image/undefined HTTP/1.1[0m" 200 -
[2020-09-14 22:04:22,973][werkzeug][INFO] - 127.0.0.1 - - [14/Sep/2020 22:04:22] "[37mGET /set_filter/none/all/none/no/none HTTP/1.1[0m" 200 -
[2020-09-14 22:04:23,004][werkzeug][INFO] - 127.0.0.1 - - [14/Sep/2020 22:04:23] "[37mGET /get_label_value_on_image/none/0103_15_07_56_i4981_id276_cn1578064077907896000_thr540.In%20.jpg HTTP/1.1[0m" 200 -
[2020-09-14 22:04:23,007][werkzeug][INFO] - 127.0.0.1 - - [14/Sep/2020 22:04:23] "[37mGET /marked_image/0103_15_07_56_i4981_id276_cn1578064077907896000_thr540.In%20.jpg HTTP/1.1[0m" 200 -
[2020-09-14 22:04:26,031][werkzeug][INFO] - 127.0.0.1 - - [14/Sep/2020 22:04:26] "[37mGET /set_filter/none/all/person/no/none HTTP/1.1[0m" 200 -
[2020-09-14 22:04:26,060][werkzeug][INFO] - 127.0.0.1 - - [14/Sep/2020 22:04:26] "[37mGET /get_label_value_on_image/person/0103_15_07_56_i4981_id276_cn1578064077907896000_thr540.In%20.jpg HTTP/1.1[0m" 200 -
[2020-09-14 22:04:29,222][werkzeug][INFO] - 127.0.0.1 - - [14/Sep/2020 22:04:29] "[37mGET /set_filter/none/all/person/yes/none HTTP/1.1[0m" 200 -
[2020-09-14 22:04:29,226][w3classifier.app][ERROR] - Exception on /get_label_value_on_image/person/undefined [GET]
Traceback (most recent call last):
  File "/home/imt/.local/lib/python3.6/site-packages/pandas/core/indexes/base.py", line 2646, in get_loc
    return self._engine.get_loc(key)
  File "pandas/_libs/index.pyx", line 111, in pandas._libs.index.IndexEngine.get_loc
  File "pandas/_libs/index.pyx", line 138, in pandas._libs.index.IndexEngine.get_loc
  File "pandas/_libs/hashtable_class_helper.pxi", line 1619, in pandas._libs.hashtable.PyObjectHashTable.get_item
  File "pandas/_libs/hashtable_class_helper.pxi", line 1627, in pandas._libs.hashtable.PyObjectHashTable.get_item
KeyError: 'undefined'

During handling of the above exception, another exception occurred:

Traceback (most recent call last):
  File "/usr/local/lib/python3.6/dist-packages/flask/app.py", line 2447, in wsgi_app
    response = self.full_dispatch_request()
  File "/usr/local/lib/python3.6/dist-packages/flask/app.py", line 1952, in full_dispatch_request
    rv = self.handle_user_exception(e)
  File "/usr/local/lib/python3.6/dist-packages/flask_cors/extension.py", line 161, in wrapped_function
    return cors_after_request(app.make_response(f(*args, **kwargs)))
  File "/usr/local/lib/python3.6/dist-packages/flask/app.py", line 1821, in handle_user_exception
    reraise(exc_type, exc_value, tb)
  File "/usr/local/lib/python3.6/dist-packages/flask/_compat.py", line 39, in reraise
    raise value
  File "/usr/local/lib/python3.6/dist-packages/flask/app.py", line 1950, in full_dispatch_request
    rv = self.dispatch_request()
  File "/usr/local/lib/python3.6/dist-packages/flask/app.py", line 1936, in dispatch_request
    return self.view_functions[rule.endpoint](**req.view_args)
  File "/home/imt/work/pyqt5-images-classifier/w3classifier/app/views.py", line 59, in get_label_value_on_image
    return jsonify(dbs.get_label_value_on_image(label, im))
  File "/home/imt/work/pyqt5-images-classifier/w3classifier/app/module.py", line 214, in get_label_value_on_image
    return {'imlabel': self.main.at[im, label]}
  File "/home/imt/.local/lib/python3.6/site-packages/pandas/core/indexing.py", line 2179, in __getitem__
    return self.obj._get_value(*key, takeable=self._takeable)
  File "/home/imt/.local/lib/python3.6/site-packages/pandas/core/frame.py", line 2919, in _get_value
    index = self.index.get_loc(index)
  File "/home/imt/.local/lib/python3.6/site-packages/pandas/core/indexes/base.py", line 2648, in get_loc
    return self._engine.get_loc(self._maybe_cast_indexer(key))
  File "pandas/_libs/index.pyx", line 111, in pandas._libs.index.IndexEngine.get_loc
  File "pandas/_libs/index.pyx", line 138, in pandas._libs.index.IndexEngine.get_loc
  File "pandas/_libs/hashtable_class_helper.pxi", line 1619, in pandas._libs.hashtable.PyObjectHashTable.get_item
  File "pandas/_libs/hashtable_class_helper.pxi", line 1627, in pandas._libs.hashtable.PyObjectHashTable.get_item
KeyError: 'undefined'
[2020-09-14 22:04:29,227][werkzeug][INFO] - 127.0.0.1 - - [14/Sep/2020 22:04:29] "[35m[1mGET /get_label_value_on_image/person/undefined HTTP/1.1[0m" 500 -
[2020-09-14 22:04:29,228][werkzeug][INFO] - 127.0.0.1 - - [14/Sep/2020 22:04:29] "[37mGET /marked_image/undefined HTTP/1.1[0m" 200 -
[2020-09-14 22:04:58,503][werkzeug][INFO] - 127.0.0.1 - - [14/Sep/2020 22:04:58] "[37mGET /marked_image/undefined HTTP/1.1[0m" 200 -
[2020-09-14 22:04:58,519][werkzeug][INFO] - 127.0.0.1 - - [14/Sep/2020 22:04:58] "[37mGET /set_filter/none/all/none/no/none HTTP/1.1[0m" 200 -
[2020-09-14 22:04:58,550][werkzeug][INFO] - 127.0.0.1 - - [14/Sep/2020 22:04:58] "[37mGET /get_label_value_on_image/none/0103_15_07_56_i4981_id276_cn1578064077907896000_thr540.In%20.jpg HTTP/1.1[0m" 200 -
[2020-09-14 22:04:58,555][werkzeug][INFO] - 127.0.0.1 - - [14/Sep/2020 22:04:58] "[37mGET /marked_image/0103_15_07_56_i4981_id276_cn1578064077907896000_thr540.In%20.jpg HTTP/1.1[0m" 200 -
[2020-09-14 22:05:03,279][werkzeug][INFO] - 127.0.0.1 - - [14/Sep/2020 22:05:03] "[37mGET /marked_image/undefined HTTP/1.1[0m" 200 -
[2020-09-14 22:05:03,280][werkzeug][INFO] - 127.0.0.1 - - [14/Sep/2020 22:05:03] "[37mGET /set_filter/none/all/none/no/none HTTP/1.1[0m" 200 -
[2020-09-14 22:05:03,314][werkzeug][INFO] - 127.0.0.1 - - [14/Sep/2020 22:05:03] "[37mGET /get_label_value_on_image/none/0103_15_07_56_i4981_id276_cn1578064077907896000_thr540.In%20.jpg HTTP/1.1[0m" 200 -
[2020-09-14 22:05:03,317][werkzeug][INFO] - 127.0.0.1 - - [14/Sep/2020 22:05:03] "[37mGET /marked_image/0103_15_07_56_i4981_id276_cn1578064077907896000_thr540.In%20.jpg HTTP/1.1[0m" 200 -
[2020-09-14 22:05:29,854][werkzeug][INFO] - 127.0.0.1 - - [14/Sep/2020 22:05:29] "[37mGET /set_filter/none/all/person/no/none HTTP/1.1[0m" 200 -
[2020-09-14 22:05:29,882][werkzeug][INFO] - 127.0.0.1 - - [14/Sep/2020 22:05:29] "[37mGET /get_label_value_on_image/person/0103_15_07_56_i4981_id276_cn1578064077907896000_thr540.In%20.jpg HTTP/1.1[0m" 200 -
[2020-09-14 22:06:32,591][werkzeug][INFO] - 127.0.0.1 - - [14/Sep/2020 22:06:32] "[37mGET /marked_image/undefined HTTP/1.1[0m" 200 -
[2020-09-14 22:06:32,610][werkzeug][INFO] - 127.0.0.1 - - [14/Sep/2020 22:06:32] "[37mGET /set_filter/none/all/none/no/none HTTP/1.1[0m" 200 -
[2020-09-14 22:06:32,648][werkzeug][INFO] - 127.0.0.1 - - [14/Sep/2020 22:06:32] "[37mGET /get_label_value_on_image/none/0103_15_07_56_i4981_id276_cn1578064077907896000_thr540.In%20.jpg HTTP/1.1[0m" 200 -
[2020-09-14 22:06:32,651][werkzeug][INFO] - 127.0.0.1 - - [14/Sep/2020 22:06:32] "[37mGET /marked_image/0103_15_07_56_i4981_id276_cn1578064077907896000_thr540.In%20.jpg HTTP/1.1[0m" 200 -
[2020-09-14 22:06:40,217][werkzeug][INFO] - 127.0.0.1 - - [14/Sep/2020 22:06:40] "[37mGET /marked_image/undefined HTTP/1.1[0m" 200 -
[2020-09-14 22:06:40,241][werkzeug][INFO] - 127.0.0.1 - - [14/Sep/2020 22:06:40] "[37mGET /set_filter/none/all/none/no/none HTTP/1.1[0m" 200 -
[2020-09-14 22:06:40,268][werkzeug][INFO] - 127.0.0.1 - - [14/Sep/2020 22:06:40] "[37mGET /get_label_value_on_image/none/0103_15_07_56_i4981_id276_cn1578064077907896000_thr540.In%20.jpg HTTP/1.1[0m" 200 -
[2020-09-14 22:06:40,270][werkzeug][INFO] - 127.0.0.1 - - [14/Sep/2020 22:06:40] "[37mGET /marked_image/0103_15_07_56_i4981_id276_cn1578064077907896000_thr540.In%20.jpg HTTP/1.1[0m" 200 -
[2020-09-14 22:06:41,611][werkzeug][INFO] - 127.0.0.1 - - [14/Sep/2020 22:06:41] "[37mGET /set_filter/none/all/person/no/none HTTP/1.1[0m" 200 -
[2020-09-14 22:06:41,639][werkzeug][INFO] - 127.0.0.1 - - [14/Sep/2020 22:06:41] "[37mGET /get_label_value_on_image/person/0103_15_07_56_i4981_id276_cn1578064077907896000_thr540.In%20.jpg HTTP/1.1[0m" 200 -
[2020-09-14 22:06:45,249][werkzeug][INFO] - 127.0.0.1 - - [14/Sep/2020 22:06:45] "[37mGET /set_filter/none/all/person/yes/none HTTP/1.1[0m" 200 -
[2020-09-14 22:06:45,253][w3classifier.app][ERROR] - Exception on /get_label_value_on_image/person/undefined [GET]
Traceback (most recent call last):
  File "/home/imt/.local/lib/python3.6/site-packages/pandas/core/indexes/base.py", line 2646, in get_loc
    return self._engine.get_loc(key)
  File "pandas/_libs/index.pyx", line 111, in pandas._libs.index.IndexEngine.get_loc
  File "pandas/_libs/index.pyx", line 138, in pandas._libs.index.IndexEngine.get_loc
  File "pandas/_libs/hashtable_class_helper.pxi", line 1619, in pandas._libs.hashtable.PyObjectHashTable.get_item
  File "pandas/_libs/hashtable_class_helper.pxi", line 1627, in pandas._libs.hashtable.PyObjectHashTable.get_item
KeyError: 'undefined'

During handling of the above exception, another exception occurred:

Traceback (most recent call last):
  File "/usr/local/lib/python3.6/dist-packages/flask/app.py", line 2447, in wsgi_app
    response = self.full_dispatch_request()
  File "/usr/local/lib/python3.6/dist-packages/flask/app.py", line 1952, in full_dispatch_request
    rv = self.handle_user_exception(e)
  File "/usr/local/lib/python3.6/dist-packages/flask_cors/extension.py", line 161, in wrapped_function
    return cors_after_request(app.make_response(f(*args, **kwargs)))
  File "/usr/local/lib/python3.6/dist-packages/flask/app.py", line 1821, in handle_user_exception
    reraise(exc_type, exc_value, tb)
  File "/usr/local/lib/python3.6/dist-packages/flask/_compat.py", line 39, in reraise
    raise value
  File "/usr/local/lib/python3.6/dist-packages/flask/app.py", line 1950, in full_dispatch_request
    rv = self.dispatch_request()
  File "/usr/local/lib/python3.6/dist-packages/flask/app.py", line 1936, in dispatch_request
    return self.view_functions[rule.endpoint](**req.view_args)
  File "/home/imt/work/pyqt5-images-classifier/w3classifier/app/views.py", line 59, in get_label_value_on_image
    return jsonify(dbs.get_label_value_on_image(label, im))
  File "/home/imt/work/pyqt5-images-classifier/w3classifier/app/module.py", line 214, in get_label_value_on_image
    return {'imlabel': self.main.at[im, label]}
  File "/home/imt/.local/lib/python3.6/site-packages/pandas/core/indexing.py", line 2179, in __getitem__
    return self.obj._get_value(*key, takeable=self._takeable)
  File "/home/imt/.local/lib/python3.6/site-packages/pandas/core/frame.py", line 2919, in _get_value
    index = self.index.get_loc(index)
  File "/home/imt/.local/lib/python3.6/site-packages/pandas/core/indexes/base.py", line 2648, in get_loc
    return self._engine.get_loc(self._maybe_cast_indexer(key))
  File "pandas/_libs/index.pyx", line 111, in pandas._libs.index.IndexEngine.get_loc
  File "pandas/_libs/index.pyx", line 138, in pandas._libs.index.IndexEngine.get_loc
  File "pandas/_libs/hashtable_class_helper.pxi", line 1619, in pandas._libs.hashtable.PyObjectHashTable.get_item
  File "pandas/_libs/hashtable_class_helper.pxi", line 1627, in pandas._libs.hashtable.PyObjectHashTable.get_item
KeyError: 'undefined'
[2020-09-14 22:06:45,254][werkzeug][INFO] - 127.0.0.1 - - [14/Sep/2020 22:06:45] "[35m[1mGET /get_label_value_on_image/person/undefined HTTP/1.1[0m" 500 -
[2020-09-14 22:06:45,255][werkzeug][INFO] - 127.0.0.1 - - [14/Sep/2020 22:06:45] "[37mGET /marked_image/undefined HTTP/1.1[0m" 200 -
[2020-09-14 22:06:46,947][werkzeug][INFO] - 127.0.0.1 - - [14/Sep/2020 22:06:46] "[37mGET /set_filter/none/all/person/no/none HTTP/1.1[0m" 200 -
[2020-09-14 22:06:46,969][werkzeug][INFO] - 127.0.0.1 - - [14/Sep/2020 22:06:46] "[37mGET /get_label_value_on_image/person/0103_15_07_56_i4981_id276_cn1578064077907896000_thr540.In%20.jpg HTTP/1.1[0m" 200 -
[2020-09-14 22:08:58,491][werkzeug][INFO] - 127.0.0.1 - - [14/Sep/2020 22:08:58] "[37mGET /set_filter/none/all/person/no/none HTTP/1.1[0m" 200 -
[2020-09-14 22:08:58,538][werkzeug][INFO] - 127.0.0.1 - - [14/Sep/2020 22:08:58] "[37mGET /get_label_value_on_image/person/0103_15_07_56_i4981_id276_cn1578064077907896000_thr540.In%20.jpg HTTP/1.1[0m" 200 -
[2020-09-14 22:10:50,519][werkzeug][INFO] - 127.0.0.1 - - [14/Sep/2020 22:10:50] "[37mGET /marked_image/undefined HTTP/1.1[0m" 200 -
[2020-09-14 22:10:50,538][werkzeug][INFO] - 127.0.0.1 - - [14/Sep/2020 22:10:50] "[37mGET /set_filter/none/all/none/no/none HTTP/1.1[0m" 200 -
[2020-09-14 22:10:50,592][werkzeug][INFO] - 127.0.0.1 - - [14/Sep/2020 22:10:50] "[37mGET /get_label_value_on_image/none/0103_15_07_56_i4981_id276_cn1578064077907896000_thr540.In%20.jpg HTTP/1.1[0m" 200 -
[2020-09-14 22:10:50,595][werkzeug][INFO] - 127.0.0.1 - - [14/Sep/2020 22:10:50] "[37mGET /marked_image/0103_15_07_56_i4981_id276_cn1578064077907896000_thr540.In%20.jpg HTTP/1.1[0m" 200 -
[2020-09-14 22:10:55,545][werkzeug][INFO] - 127.0.0.1 - - [14/Sep/2020 22:10:55] "[37mGET /set_filter/none/all/person/no/none HTTP/1.1[0m" 200 -
[2020-09-14 22:10:55,575][werkzeug][INFO] - 127.0.0.1 - - [14/Sep/2020 22:10:55] "[37mGET /get_label_value_on_image/person/0103_15_07_56_i4981_id276_cn1578064077907896000_thr540.In%20.jpg HTTP/1.1[0m" 200 -
[2020-09-14 22:15:22,808][werkzeug][INFO] - 127.0.0.1 - - [14/Sep/2020 22:15:22] "[37mGET /marked_image/undefined HTTP/1.1[0m" 200 -
[2020-09-14 22:15:22,825][werkzeug][INFO] - 127.0.0.1 - - [14/Sep/2020 22:15:22] "[37mGET /set_filter/none/all/none/no/none HTTP/1.1[0m" 200 -
[2020-09-14 22:15:22,859][werkzeug][INFO] - 127.0.0.1 - - [14/Sep/2020 22:15:22] "[37mGET /get_label_value_on_image/none/0103_15_07_56_i4981_id276_cn1578064077907896000_thr540.In%20.jpg HTTP/1.1[0m" 200 -
[2020-09-14 22:15:22,862][werkzeug][INFO] - 127.0.0.1 - - [14/Sep/2020 22:15:22] "[37mGET /marked_image/0103_15_07_56_i4981_id276_cn1578064077907896000_thr540.In%20.jpg HTTP/1.1[0m" 200 -
[2020-09-14 22:15:30,938][werkzeug][INFO] - 127.0.0.1 - - [14/Sep/2020 22:15:30] "[37mGET /set_filter/none/all/person/no/none HTTP/1.1[0m" 200 -
[2020-09-14 22:15:30,972][werkzeug][INFO] - 127.0.0.1 - - [14/Sep/2020 22:15:30] "[37mGET /get_label_value_on_image/person/0103_15_07_56_i4981_id276_cn1578064077907896000_thr540.In%20.jpg HTTP/1.1[0m" 200 -
[2020-09-14 22:15:35,949][werkzeug][INFO] - 127.0.0.1 - - [14/Sep/2020 22:15:35] "[37mGET /set_filter/none/all/person/yes/none HTTP/1.1[0m" 200 -
[2020-09-14 22:15:35,953][w3classifier.app][ERROR] - Exception on /get_label_value_on_image/person/undefined [GET]
Traceback (most recent call last):
  File "/home/imt/.local/lib/python3.6/site-packages/pandas/core/indexes/base.py", line 2646, in get_loc
    return self._engine.get_loc(key)
  File "pandas/_libs/index.pyx", line 111, in pandas._libs.index.IndexEngine.get_loc
  File "pandas/_libs/index.pyx", line 138, in pandas._libs.index.IndexEngine.get_loc
  File "pandas/_libs/hashtable_class_helper.pxi", line 1619, in pandas._libs.hashtable.PyObjectHashTable.get_item
  File "pandas/_libs/hashtable_class_helper.pxi", line 1627, in pandas._libs.hashtable.PyObjectHashTable.get_item
KeyError: 'undefined'

During handling of the above exception, another exception occurred:

Traceback (most recent call last):
  File "/usr/local/lib/python3.6/dist-packages/flask/app.py", line 2447, in wsgi_app
    response = self.full_dispatch_request()
  File "/usr/local/lib/python3.6/dist-packages/flask/app.py", line 1952, in full_dispatch_request
    rv = self.handle_user_exception(e)
  File "/usr/local/lib/python3.6/dist-packages/flask_cors/extension.py", line 161, in wrapped_function
    return cors_after_request(app.make_response(f(*args, **kwargs)))
  File "/usr/local/lib/python3.6/dist-packages/flask/app.py", line 1821, in handle_user_exception
    reraise(exc_type, exc_value, tb)
  File "/usr/local/lib/python3.6/dist-packages/flask/_compat.py", line 39, in reraise
    raise value
  File "/usr/local/lib/python3.6/dist-packages/flask/app.py", line 1950, in full_dispatch_request
    rv = self.dispatch_request()
  File "/usr/local/lib/python3.6/dist-packages/flask/app.py", line 1936, in dispatch_request
    return self.view_functions[rule.endpoint](**req.view_args)
  File "/home/imt/work/pyqt5-images-classifier/w3classifier/app/views.py", line 59, in get_label_value_on_image
    return jsonify(dbs.get_label_value_on_image(label, im))
  File "/home/imt/work/pyqt5-images-classifier/w3classifier/app/module.py", line 214, in get_label_value_on_image
    return {'imlabel': self.main.at[im, label]}
  File "/home/imt/.local/lib/python3.6/site-packages/pandas/core/indexing.py", line 2179, in __getitem__
    return self.obj._get_value(*key, takeable=self._takeable)
  File "/home/imt/.local/lib/python3.6/site-packages/pandas/core/frame.py", line 2919, in _get_value
    index = self.index.get_loc(index)
  File "/home/imt/.local/lib/python3.6/site-packages/pandas/core/indexes/base.py", line 2648, in get_loc
    return self._engine.get_loc(self._maybe_cast_indexer(key))
  File "pandas/_libs/index.pyx", line 111, in pandas._libs.index.IndexEngine.get_loc
  File "pandas/_libs/index.pyx", line 138, in pandas._libs.index.IndexEngine.get_loc
  File "pandas/_libs/hashtable_class_helper.pxi", line 1619, in pandas._libs.hashtable.PyObjectHashTable.get_item
  File "pandas/_libs/hashtable_class_helper.pxi", line 1627, in pandas._libs.hashtable.PyObjectHashTable.get_item
KeyError: 'undefined'
[2020-09-14 22:15:35,954][werkzeug][INFO] - 127.0.0.1 - - [14/Sep/2020 22:15:35] "[37mGET /marked_image/undefined HTTP/1.1[0m" 200 -
[2020-09-14 22:15:35,955][werkzeug][INFO] - 127.0.0.1 - - [14/Sep/2020 22:15:35] "[35m[1mGET /get_label_value_on_image/person/undefined HTTP/1.1[0m" 500 -
[2020-09-14 22:15:38,294][werkzeug][INFO] - 127.0.0.1 - - [14/Sep/2020 22:15:38] "[37mGET /set_filter/none/all/person/no/none HTTP/1.1[0m" 200 -
[2020-09-14 22:15:38,320][werkzeug][INFO] - 127.0.0.1 - - [14/Sep/2020 22:15:38] "[37mGET /get_label_value_on_image/person/0103_15_07_56_i4981_id276_cn1578064077907896000_thr540.In%20.jpg HTTP/1.1[0m" 200 -
