[2020-09-11 19:57:41,519][werkzeug][INFO] -  * Running on http://127.0.0.1:8081/ (Press CTRL+C to quit)
[2020-09-11 19:57:55,035][w3classifier.app][ERROR] - Exception on /set_filter/none/all/none/no/none [GET]
Traceback (most recent call last):
  File "/usr/local/lib/python3.6/dist-packages/flask/app.py", line 2447, in wsgi_app
    response = self.full_dispatch_request()
  File "/usr/local/lib/python3.6/dist-packages/flask/app.py", line 1952, in full_dispatch_request
    rv = self.handle_user_exception(e)
  File "/usr/local/lib/python3.6/dist-packages/flask_cors/extension.py", line 161, in wrapped_function
    return cors_after_request(app.make_response(f(*args, **kwargs)))
  File "/usr/local/lib/python3.6/dist-packages/flask/app.py", line 1821, in handle_user_exception
    reraise(exc_type, exc_value, tb)
  File "/usr/local/lib/python3.6/dist-packages/flask/_compat.py", line 39, in reraise
    raise value
  File "/usr/local/lib/python3.6/dist-packages/flask/app.py", line 1950, in full_dispatch_request
    rv = self.dispatch_request()
  File "/usr/local/lib/python3.6/dist-packages/flask/app.py", line 1936, in dispatch_request
    return self.view_functions[rule.endpoint](**req.view_args)
  File "/home/imt/work/pyqt5-images-classifier/w3classifier/app/views.py", line 53, in set_filter
    resp = jsonify(dbs.set_filter(label, value, seek_label, seek_only_clear, size))
  File "/home/imt/work/pyqt5-images-classifier/w3classifier/app/module.py", line 185, in set_filter
    print(f'{label}={value} {count_nonzero(f2)}')
UnboundLocalError: local variable 'f2' referenced before assignment
[2020-09-11 19:57:55,036][werkzeug][INFO] - 127.0.0.1 - - [11/Sep/2020 19:57:55] "[37mGET /marked_image/undefined HTTP/1.1[0m" 200 -
[2020-09-11 19:57:55,038][werkzeug][INFO] - 127.0.0.1 - - [11/Sep/2020 19:57:55] "[35m[1mGET /set_filter/none/all/none/no/none HTTP/1.1[0m" 500 -
